Workbook
Name Derslik: #REF!
Name Derslik: #REF!
Name Islem: #REF!
Name Islem: #REF!
Name Kadrolu: #REF!
Name Kadrolu: #REF!
Name statü: #REF!
Name statü: #REF!
Name Unvan: #REF!
Name Unvan: #REF!
Name Unvan2: #REF!
Name Unvan2: #REF!
Name yarıyıl: #REF!
Name yarıyıl: #REF!

Sheet KAT_PLANI
A2: KAT : 0 | G2: KAT : 1 | M2: KAT : 2
A3: SINIF KODU | C3: SINIF KAPASİTESİ | D3: ÖĞRENCİ KAPASİTESİ | G3: SINIF KODU | I3: SINIF KAPASİTESİ | J3: ÖĞRENCİ KAPASİTESİ | M3: SINIF KODU | O3: SINIF KAPASİTESİ | P3: ÖĞRENCİ KAPASİTESİ
A4: L 002 | B4: Film/stüd. | G4: C 101 | H4: Duruşma Salonu | I4: 35 | J4: 30 | K4: HF | M4: C 208 | O4: 30 | P4: 30 | Q4: Hazırlık Okulu
A5: C 003 | B5: DİJİTAL MED LAB | C5: 30 | D5: 30 | E5: GSTF | G5: C 102 | I5: 30 | J5: 30 | K5: GSTF | M5: C 213 | O5: 30 | P5: 30 | Q5: Hazırlık Okulu
A6: C 005 | C6: 57 | D6: 45 | E6: Müzik | G6: C 103 | H6: PSY LAB | I6: 30 | K6: İTBF | M6: C 214 | O6: 30 | P6: 30 | Q6: İTBF
A7: C 006 | C7: 37 | D7: 30 | E7: Hazırlık Okulu | G7: C 104 | I7: 50 | J7: 50 | K7: İTBF | M7: C 215 | O7: 45 | P7: 45 | Q7: İTBF
A8: C 007 | B8: İ/M STD1 | C8: 34 | D8: 31 | E8: GSTF | G8: C 109 | I8: 50 | J8: 50 | K8: İTBF | M8: C 220 | O8: 25 | P8: 25 | Q8: İTBF
A9: L 008 | B9: M/T Lab | C9: 20 | E9: İTBF | G9: C 113 | I9: 45 | J9: 45 | K9: İTBF | M9: C 221 | O9: 30 | P9: 30 | Q9: İTBF
A10: C 012 | B10: İ/M STD2 | C10: 70 | D10: 70 | E10: GSTF | G10: C 114 | I10: 30 | J10: 30 | K10: Hazırlık Okulu | M10: C 222 | O10: 30 | P10: 30 | Q10: İTBF
A11: C 013 | B11: İ/M STD3 | C11: 40 | D11: 40 | E11: GSTF | G11: L 115 | H11: BİLG 4 | I11: 30 | K11: GSTF | M11: C 229 | O11: 40 | P11: 40 | Q11: İTBF
A12: C 017 | C12: 85 | D12: 83 | E12: MMF | G12: L 121 | H12: BIL LAB | I12: 30 | J12: 30 | K12: MMF-Lab | M12: C 230 | O12: 40 | P12: 40 | Q12: İTBF
A13: C 018 | C13: 88 | D13: 88 | E13: MMF | G13: C 122 | I13: 40 | J13: 30 | K13: Hazırlık Okulu | M13: C 231 | O13: 60 | P13: 60 | Q13: HF
A14: C 025 | C14: 88 | D14: 65 | E14: MMF | G14: C 123 | I14: 35 | J14: 30 | K14: Hazırlık Okulu | M14: C 232 | O14: 60 | P14: 60 | Q14: İTBF
A15: C 026 | C15: 84 | D15: 48 | E15: MMF | G15: C 130 | I15: 30 | J15: 30 | K15: Hazırlık Okulu | M15: C 233 | O15: 45 | P15: 45 | Q15: İTBF
A16: C 027 | C16: 88 | D16: 76 | E16: ITBF | G16: C 131 | I16: 30 | J16: 30 | K16: Hazırlık Okulu | M16: AMFİ4 | N16: GSTF | O16: 82 | P16: 82 | Q16: ITBF
A17: C 034 | C17: 88 | D17: 78 | E17: HF | G17: C 132 | I17: 30 | J17: 30 | K17: Hazırlık Okulu | M17: AMFİ3 | N17: HUK | O17: 106 | P17: 106 | Q17: HF
A18: C 035 | C18: 85 | D18: 67 | E18: HF | G18: L 139 | H18: SHGM Sınav Merkezi | I18: 30 | K18: MMF-Lab | M18: AMFİ2 | N18: İTBF | O18: 106 | P18: 106 | Q18: GSTF
A19: C 036 | C19: 102 | D19: 86 | E19: MMF | G19: L 140 | H19: Elk./Eln. Lab | I19: 40 | K19: MMF-Lab | M19: AMFİ1 | N19: MMF | O19: 111 | P19: 111 | Q19: MMF
A20: L 037 | B20: İHA-LAB | C20: 10 | E20: MYO | G20: L 141 | H20: Bilg.Lab-2 | I20: 40 | K20: MMF-Lab | M20: AMFİ 5 | N20: ANK | O20: 222
A21: C 053 | C21: 56 | D21: 35 | E21: MYO | G21: L 142 | H21: Bilg.Lab-3 | I21: 30 | K21: MMF-Lab | O21: =SUM(O4:O20) -> 1092 | P21: =SUM(P4:P20) -> 870
A22: C 054 | C22: 31 | D22: 31 | E22: MMF | G22: L 143 | H22: Fizik Lab | I22: 30 | K22: MMF-Lab
A23: C 055 | C23: 54 | D23: 49 | E23: MYO | I23: =SUM(I4:I22) -> 665 | J23: =SUM(J4:J22) -> 415
A24: C 056 | B24: BİLG 5 | C24: 30 | E24: MMF-Lab | N24: Snf.Kap. | O24: Öğr.Kap.
A25: LECTURE HALL 5 | C25: 90 | D25: 90 | E25: İTBF | M25: TOPLAM | N25: =C48+I23+O21 -> 3778 | O25: =D48+J23+P21 -> 3045
A26: LECTURE HALL 6 | C26: 30 | D26: 30 | E26: MMF
A27: LECTURE HALL 7 | C27: 54 | D27: 54 | E27: İTBF
A28: C 060 | C28: 17 | D28: 17 | E28: İTBF
A29: C 063 | B29: COM. LAB | C29: 24 | D29: 24 | E29: MYO
A30: C 070 | C30: 30 | D30: 29 | E30: GSTF
A31: C071 | C31: 40 | D31: 40 | E31: GSTF
A32: C 072 | C32: 34 | D32: 33 | E32: MMF
A33: C 073 | C33: 65 | D33: 53 | E33: İTBF
A34: C 074 | C34: 63 | D34: 63 | E34: MMF
A35: C 075 | C35: 39 | D35: 39 | E35: MMF
A36: C 076 | C36: 35 | D36: 33 | E36: Hazırlık Okulu
A37: C 077 | C37: 24 | D37: 24 | E37: Hazırlık Okulu
A38: C 078 | C38: 30 | D38: 28 | E38: Hazırlık Okulu
A39: C 084 | C39: 26 | D39: 21 | E39: Hazırlık Okulu
A40: C 085 | C40: 37 | D40: 36 | E40: MYO
A41: C 086 | C41: 54 | D41: 42 | E41: MYO
...

Sheet DERS_PLANI
B1: ANKARA BİLİM ÜNİVERSİTESİ
A2: 3 | B2: 2025-2026 ÖĞRETİM YILI BAHAR DÖNEMİ
B3: MALTEPE KAMPÜSÜ DERSLİK PROGRAMI
B5: Gün | C5: Saat | E5: C 208 | F5: C 213 | G5: C 214 | H5: C 215 | I5: C 220 | J5: C 221 | K5: C 222 | L5: C 229 | M5: C 230 | N5: C 231 | O5: C 232 | P5: C 233 | Q5: AMFİ4 | R5: AMFİ3 | S5: AMFİ2 | T5: AMFİ1 | U5: AMFİ 5 | V5: Online | W5: Online | X5: Online | Y5: Online
E7: Hazırlık Okulu | F7: Hazırlık Okulu | G7: ITBF | H7: İTBF | I7: İTBF | J7: İTBF | K7: İTBF | L7: İTBF | M7: İTBF | N7: HF | O7: İTBF | P7: İTBF | Q7: ITBF | R7: HF | S7: GSTF | T7: MMF
A8: ÜST KAT | B8: Pazartesi | C8: 1 | D8: 09:00 - 09:50 | H8: ETI 208 (Dr. Akbay) | I8: YBS 261 TİCARİ İSTİHBARAT SERTAÇ- ÖZGÜL HOCALAR | J8: CMM 211-Philosophy of Technology and Society | K8: BUS 304 (Dr. Özgül) | M8: BUS 102 (Dr. Kalkan) | N8: SEC329/CMM 329 | O8: ETI 112 (Dr. Acar)
C9: 2 | D9: 09:55 - 10:45 | H9: ETI 208 (Dr. Akbay) | I9: YBS 261 TİCARİ İSTİHBARAT SERTAÇ- ÖZGÜL HOCALAR | J9: CMM 211-Philosophy of Technology and Society | K9: BUS 304 (Dr. Özgül) | M9: BUS 102 (Dr. Kalkan) | N9: SEC329/CMM 329 | O9: ETI 112 (Dr. Acar) | Q9: MYO IHA104 İHA SİSTEMLERİ ÜRETİM VE TESTLERİ | T9: MATH 101 (Teorik) - Sec 1 (Mustafa Akkaya)
C10: 3 | D10: 10:50 - 11:40 | H10: ETI 208 (Dr. Akbay) | I10: YBS 261 TİCARİ İSTİHBARAT SERTAÇ- ÖZGÜL HOCALAR | J10: CMM 211-Philosophy of Technology and Society | K10: BUS 304 (Dr. Özgül) | L10: OC 160 Diplomasi Atölyesi | M10: BUS 102 (Dr. Kalkan) | N10: SEC329 | O10: ETI 112 (Dr. Acar) | Q10: MYO IHA104 İHA SİSTEMLERİ ÜRETİM VE TESTLERİ | T10: MATH 101 (Teorik) - Sec 1 (Mustafa Akkaya)
C11: 4 | D11: 12:20 - 13:10 | H11: CMM 176 Psikopatik Çağda İnsan | I11: SİMURG SENİOR | J11: POLS 306 (Assoc. Prof. Köni) | L11: SİMURG MASTERCLASS | N11: HUK306 | O11: ETI 110 (Dr. Akbay) | P11: ETI 264 (Doç. Düzgün) | Q11: MYO IHA104 İHA SİSTEMLERİ ÜRETİM VE TESTLERİ | R11: YBS 457 TEDARİK ZİNCİRİ YÖNETİMİ DR. ADİL AKKUŞ | T11: Protokol Eğitimi
C12: 5 | D12: 13:15 - 14:05 | H12: CMM 176 Psikopatik Çağda İnsan | I12: SİMURG SENİOR | J12: POLS 306 (Assoc. Prof. Köni) | L12: SİMURG MASTERCLASS | N12: HUK306 | O12: ETI 110 (Dr. Akbay) | P12: ETI 264 (Doç. Düzgün) | Q12: MYO IHA104 İHA SİSTEMLERİ ÜRETİM VE TESTLERİ | R12: YBS 457 TEDARİK ZİNCİRİ YÖNETİMİ DR. ADİL AKKUŞ | S12: FAD 110 | T12: Protokol Eğitimi
C13: 6 | D13: 14:10 - 15:00 | H13: CMM 176 Psikopatik Çağda İnsan | I13: SİMURG SENİOR | J13: POLS 306 (Assoc. Prof. Köni) | L13: SİMURG MASTERCLASS | N13: HUK306 | O13: ETI 110 (Dr. Akbay) | P13: ETI 264 (Doç. Düzgün) | R13: YBS 457 TEDARİK ZİNCİRİ YÖNETİMİ DR. ADİL AKKUŞ | S13: FAD 110 | T13: Protokol Eğitimi
C14: 7 | D14: 15:20 - 16:10 | G14: CMM 174 Media, Politics and Power | I14: SİMURG SENİOR | K14: GER 202 (01) (Öğr. Gör. Yılmaz) | L14: SİMURG MASTERCLASS | N14: HUK306 | P14: MIS 251 Dr. Koçanlı | S14: FAD 110 | T14: Protokol Eğitimi
C15: 8 | D15: 16:15 - 17:05 | G15: CMM 174 Media, Politics and Power | I15: SİMURG SEÇMELİ RUSÇA | K15: GER 202 (01) (Öğr. Gör. Yılmaz) | N15: HUK306 | P15: MIS 251 Dr. Koçanlı | T15: MATH 102 (Teorik) - Sec 3 (Mustafa Akkaya)
C16: 9 | D16: 17:10 - 18:00 | G16: CMM 174 Media, Politics and Power | K16: GER 202 (01) (Öğr. Gör. Yılmaz) | P16: MIS 251 Dr. Koçanlı | T16: MATH 102 (Teorik) - Sec 3 (Mustafa Akkaya)
C17: 10 | D17: 18.10 - 19.00 | I17: BUS 507 (Assoc. Prof. Topcu) | M17: YBS 504 (Dr. Akkuş)
C18: 11 | D18: 19.10 - 20.00 | I18: BUS 507 (Assoc. Prof. Topcu) | M18: YBS 504 (Dr. Akkuş)
C19: 12 | D19: 20.10 - 21.00 | I19: BUS 507 (Assoc. Prof. Topcu) | M19: YBS 504 (Dr. Akkuş)
B20: Salı | C20: 1 | D20: 09:00 - 09:50 | H20: MIS 469 (Dr. Kandemir) | I20: POLS 352 (Dr. Emir) | K20: BUS 302 (Dr. Akdemir) | L20: SPAN 302 | N20: HUK304 | O20: BUS 104 (Prof. Eren) | R20: HUK414 | T20: MATH 102 (Teorik) - Sec 1 (Osman Tuncay Başkaya)
C21: 2 | D21: 09:55 - 10:45 | H21: MIS 469 (Dr. Kandemir) | I21: POLS 352 (Dr. Emir) | K21: BUS 302 (Dr. Akdemir) | L21: SPAN 302 | N21: HUK304 | O21: BUS 104 (Prof. Eren) | R21: HUK414 | S21: FAD 320 | T21: MATH 102 (Teorik) - Sec 1 (Osman Tuncay Başkaya)
C22: 3 | D22: 10:50 - 11:40 | H22: MIS 469 (Dr. Kandemir) | I22: POLS 352 (Dr. Emir) | J22: OC 154 | K22: BUS 302 (Dr. Akdemir) | L22: SPAN 302 | N22: HUK304 | O22: BUS 104 (Prof. Eren) | R22: HUK414 | S22: FAD 320
C23: 4 | D23: 12:20 - 13:10 | G23: MIS 363 (Assoc. Prof. Metin) | H23: YBS 352 SOSYAL GİRİŞİMCİLİK FUAT GÜNEY | I23: SPAN 202 | K23: BUS 202 (Dr. Özgül) | L23: ENG 202 - 02 (PSY) | M23: YBS 322 KARAR DESTEK SİSTEMLERİ DR. FATMA DEMİR ERKUL | N23: HUK308 | O23: PSİ 480 (Dr. Yeşi Kocagazioğlu) | P23: CMM 202 Technical Communication & Project Design | Q23: ETI 104 (Dr. Akbay) | S23: FAD 320 | T23: PHY 102 (Teorik) - Sec 3(Vedat Tanrıverdi) | U23: OC 106 ANKARA
C24: 5 | D24: 13:15 - 14:05 | G24: MIS 363 (Assoc. Prof. Metin) | H24: YBS 352 SOSYAL GİRİŞİMCİLİK FUAT GÜNEY | I24: SPAN 202 | J24: SİMURG 2. DÖNEM | K24: BUS 202 (Dr. Özgül) | L24: ENG 202 - 02 (PSY) | M24: YBS 322 KARAR DESTEK SİSTEMLERİ DR. FATMA DEMİR ERKUL | N24: HUK308 | O24: PSİ 480 (Dr. Yeşi Kocagazioğlu) | P24: CMM 202 Technical Communication & Project Design | Q24: ETI 104 (Dr. Akbay) | R24: HUK404 | T24: PHY 102 (Teorik) - Sec 3(Vedat Tanrıverdi)
C25: 6 | D25: 14:10 - 15:00 | G25: MIS 363 (Assoc. Prof. Metin) | H25: YBS 352 SOSYAL GİRİŞİMCİLİK FUAT GÜNEY | I25: SPAN 202 | J25: SİMURG 2. DÖNEM | K25: BUS 202 (Dr. Özgül) | M25: YBS 322 KARAR DESTEK SİSTEMLERİ DR. FATMA DEMİR ERKUL | N25: HUK308 | O25: PSİ 480 (Dr. Yeşi Kocagazioğlu) | P25: CMM 202 Technical Communication & Project Design | Q25: ETI 104 (Dr. Akbay) | R25: HUK404 | T25: PHY 102 (Teorik) - Sec 3(Vedat Tanrıverdi)
C26: 7 | D26: 15:20 - 16:10 | G26: CMM 208 Turkish Political History | H26: PSİ 451 | I26: OC 174 Advanced English Speaking | J26: SİMURG 2. DÖNEM | K26: OC 174 Advanced English Speaking | R26: HUK404 | S26: FAD 332 | T26: MATH 102 (Teorik) - Sec 2 (Osman Tuncay Başkaya)
C27: 8 | D27: 16:15 - 17:05 | G27: CMM 208 Turkish Political History | H27: PSİ 451 | J27: SİMURG 2. DÖNEM | K27: OC 174 Advanced English Speaking | S27: FAD 332 | T27: MATH 102 (Teorik) - Sec 2 (Osman Tuncay Başkaya)
C28: 9 | D28: 17:10 - 18:00 | G28: CMM 208 Turkish Political History | H28: PSİ 451 | K28: OC 174 Advanced English Speaking | S28: FAD 332
C29: 10 | D29: 18.10 - 19.00 | M29: CMM 900 Turkish for International Students
C30: 11 | D30: 19.10- 20.00 | M30: CMM 900 Turkish for International Students
C31: 12 | D31: 20.10 - 21.00 | M31: CMM 900 Turkish for International Students
B32: Çarşamba | C32: 1 | D32: 09:00 - 09:50 | G32: MIS 362 (Lect. Yolcu) | H32: PSİ 454 | J32: MIS 458 Dr. Gerdan | K32: POLS 302 (Assoc. Prof. Köni) | L32: ETI 362 (Doç. Düzgün) | M32: SOC 102 (Prof. Kes Erkul) | N32: HUK312 | O32: MIS 457 (Prof. Meydan) | P32: ETI 202 (Dr. Acar) | R32: HUK408
C33: 2 | D33: 09:55 - 10:45 | G33: MIS 362 (Lect. Yolcu) | H33: PSİ 454 | J33: MIS 458 Dr. Gerdan | K33: POLS 302 (Assoc. Prof. Köni) | L33: ETI 362 (Doç. Düzgün) | M33: SOC 102 (Prof. Kes Erkul) | N33: HUK312 | O33: MIS 457 (Prof. Meydan) | P33: ETI 202 (Dr. Acar) | R33: HUK408
C34: 3 | D34: 10:50 - 11:40 | G34: MIS 362 (Lect. Yolcu) | H34: PSİ 454 | I34: OC 153 Psikolojik Destek | J34: MIS 458 Dr. Gerdan | K34: POLS 302 (Assoc. Prof. Köni) | L34: ETI 362 (Doç. Düzgün) | M34: SOC 102 (Prof. Kes Erkul) | N34: HUK312 | O34: MIS 457 (Prof. Meydan) | P34: ETI 202 (Dr. Acar) | R34: HUK408
C35: 4 | D35: 12:20 - 13:10 | G35: POLS 308 (Dr. Aslaner) | I35: SİMURG SENİOR | J35: MIS 322 Dr. Erkul | K35: BUS 308 (Dr. Akdemir) | L35: ENG302-03 (TR YBS) | M35: ETI 376 (Dr. Acar) | N35: HUK312 | O35: MIS 112 (Prof. Meydan) | P35: ENG 302 - 01 (PSY.) | Q35: FLM 302 | S35: PSY 109
C36: 5 | D36: 13:15 - 14:05 | G36: POLS 308 (Dr. Aslaner) | H36: HUK308 | I36: SİMURG SENİOR | J36: MIS 322 Dr. Erkul | K36: BUS 308 (Dr. Akdemir) | L36: ENG302-03 (TR YBS) | M36: ETI 376 (Dr. Acar) | N36: OC 118 | O36: MIS 112 (Prof. Meydan) | P36: ENG 302 - 01 (PSY.) | Q36: FLM 302 | R36: HUK412 | S36: PSY 109 | T36: MATH 101 (Teorik) - Sec 1(Mustafa Akkaya)
C37: 6 | D37: 14:10 - 15:00 | G37: POLS 308 (Dr. Aslaner) | H37: HUK308 | I37: SİMURG SENİOR | J37: MIS 322 Dr. Erkul | K37: BUS 308 (Dr. Akdemir) | M37: ETI 376 (Dr. Acar) | N37: HUK308 | O37: MIS 112 (Prof. Meydan) | Q37: FLM 302 | R37: HUK412 | S37: PSY 109 | T37: MATH 101 (Teorik) - Sec 1(Mustafa Akkaya)
C38: 7 | D38: 15:20 - 16:10 | G38: YBS 362 MÜZAKERE TEKNİKLERİ DOÇ.DR. MÜNEVVER BAYAR | I38: SİMURG SENİOR | K38: GER 202 (02) (Öğr. Gör. Yılmaz) | M38: POLS 214 (Dr. Değirmenci) | N38: HUK308 | O38: CMM 186 İklim Değişikliği ve Ekonomi | R38: HUK412 | T38: MYO - IHA102 İTKİ SİSTEMİ SEÇİMİ VE TASARIMI
C39: 8 | D39: 16:15 - 17:05 | G39: YBS 362 MÜZAKERE TEKNİKLERİ DOÇ.DR. MÜNEVVER BAYAR | K39: GER 202 (02) (Öğr. Gör. Yılmaz) | L39: OC 166 Diksiyon | M39: POLS 214 (Dr. Değirmenci) | O39: CMM 186 İklim Değişikliği ve Ekonomi | T39: MYO - IHA102 İTKİ SİSTEMİ SEÇİMİ VE TASARIMI
C40: 9 | D40: 17:10 - 18:00 | G40: YBS 362 MÜZAKERE TEKNİKLERİ DOÇ.DR. MÜNEVVER BAYAR | I40: SİMURG SEÇMELİ İLETİŞİM | K40: GER 202 (02) (Öğr. Gör. Yılmaz) | M40: POLS 214 (Dr. Değirmenci) | O40: CMM 186 İklim Değişikliği ve Ekonomi | T40: MYO - IHA102 İTKİ SİSTEMİ SEÇİMİ VE TASARIMI
C41: 10 | D41: 18.10 - 19.00 | I41: ISL 512 (Prof. Meydan)
C42: 11 | D42: 19.10 - 20.00 | I42: ISL 512 (Prof. Meydan)
...

Sheet LECTURE HALL 5
A1: LECTURE HALL 5
A2: Saat/Gün | B2: Pazartesi | C2: Salı | D2: Çarşamba | E2: Perşembe | F2: Cuma
A3: 09.00 - 09.50 | B3: =DERS_PLANI!Z161 -> PSY 102 | C3: =DERS_PLANI!Z173 -> 0 | D3: =DERS_PLANI!Z185 -> YBS 122 İŞLETME MATEMATİĞİ II DR. ADİL AKKUŞ | E3: =DERS_PLANI!Z197 -> 0 | F3: =DERS_PLANI!Y209 -> 0
A4: 09.55 - 10.45 | B4: =DERS_PLANI!Z162 -> PSY 102 | C4: =DERS_PLANI!Z174 -> 0 | D4: =DERS_PLANI!Z186 -> YBS 122 İŞLETME MATEMATİĞİ II DR. ADİL AKKUŞ | E4: =DERS_PLANI!Z198 -> 0 | F4: =DERS_PLANI!Y210 -> CENG 332 (Lab) - Sec 1
A5: 10.50 - 11.40 | B5: =DERS_PLANI!Z163 -> PSY 102 | C5: =DERS_PLANI!Z175 -> Telafi Sınavı | D5: =DERS_PLANI!Z187 -> YBS 122 İŞLETME MATEMATİĞİ II DR. ADİL AKKUŞ | E5: =DERS_PLANI!Z199 -> 0 | F5: =DERS_PLANI!Y211 -> CENG 332 (Lab) - Sec 1
A6: 12.20 - 13.10 | B6: =DERS_PLANI!Z164 -> PSİ 102 | C6: =DERS_PLANI!Z176 -> ETI 104 (Dr. Akbay) | D6: =DERS_PLANI!Z188 -> SURD 106 SÜRDÜRÜLEBİRLİĞE GİRİŞ DR. NESLİHAN KÜNYE POLAT | E6: =DERS_PLANI!Z200 -> psi 221 | F6: =DERS_PLANI!Y212 -> 0
A7: 13.15 - 14.05 | B7: =DERS_PLANI!Z165 -> PSİ 102 | C7: =DERS_PLANI!Z177 -> ETI 104 (Dr. Akbay) | D7: =DERS_PLANI!Z189 -> SURD 106 SÜRDÜRÜLEBİRLİĞE GİRİŞ DR. NESLİHAN KÜNYE POLAT | E7: =DERS_PLANI!Z201 -> psi 221 | F7: =DERS_PLANI!Y213 -> 0
A8: 14.10 - 15.00 | B8: =DERS_PLANI!Z166 -> PSİ 102 | C8: =DERS_PLANI!Z178 -> ETI 104 (Dr. Akbay) | D8: =DERS_PLANI!Z190 -> SURD 106 SÜRDÜRÜLEBİRLİĞE GİRİŞ DR. NESLİHAN KÜNYE POLAT | E8: =DERS_PLANI!Z202 -> psi 221 | F8: =DERS_PLANI!Y214 -> 0
A9: 15.20 - 16.10 | B9: =DERS_PLANI!Z167 -> 0 | C9: =DERS_PLANI!Z179 -> 0 | D9: =DERS_PLANI!Z191 -> ENG 302-04 PSK-TR | E9: =DERS_PLANI!Z203 -> 0 | F9: =DERS_PLANI!Y215 -> BM 332 (Lab) - Sec 1
A10: 16.15 - 17.05 | B10: =DERS_PLANI!Z168 -> 0 | C10: =DERS_PLANI!Z180 -> 0 | D10: =DERS_PLANI!Z192 -> ENG 302-04 PSK-TR | E10: =DERS_PLANI!Z204 -> 0 | F10: =DERS_PLANI!Y216 -> BM 332 (Lab) - Sec 1
A11: 17.10 - 18.00 | B11: =DERS_PLANI!Z169 -> 0 | C11: =DERS_PLANI!Z181 -> 0 | D11: =DERS_PLANI!Z193 -> 0 | E11: =DERS_PLANI!Z205 -> 0 | F11: =DERS_PLANI!Y217 -> 0
A12: 18:10 - 19:00 | B12: =DERS_PLANI!Z170 -> 0 | C12: =DERS_PLANI!Z182 -> 0 | D12: =DERS_PLANI!Z194 -> 0 | E12: =DERS_PLANI!Z206 -> 0 | F12: =DERS_PLANI!Y218 -> 0
A13: 19:10 - 20:00 | B13: =DERS_PLANI!Z171 -> 0 | C13: =DERS_PLANI!Z183 -> 0 | D13: =DERS_PLANI!Z195 -> 0 | E13: =DERS_PLANI!Z207 -> 0 | F13: =DERS_PLANI!Y219 -> 0
A14: 20:10 - 21:00 | B14: =DERS_PLANI!Z172 -> 0 | C14: =DERS_PLANI!Z184 -> 0 | D14: =DERS_PLANI!Z196 -> 0 | E14: =DERS_PLANI!Z208 -> 0 | F14: =DERS_PLANI!Y220 -> 0

Sheet LECTURE HALL 6
A1: LECTURE HALL 6
A2: Saat/Gün | B2: Pazartesi | C2: Salı | D2: Çarşamba | E2: Perşembe | F2: Cuma
A3: 09.00 - 09.50 | B3: =DERS_PLANI!AA161 -> 0 | C3: =DERS_PLANI!AA173 -> 0 | D3: =DERS_PLANI!AA185 -> 0 | E3: =DERS_PLANI!AA197 -> 0 | F3: =DERS_PLANI!AA209 -> 0
A4: 09.55 - 10.45 | B4: =DERS_PLANI!AA162 -> 0 | C4: =DERS_PLANI!AA174 -> 0 | D4: =DERS_PLANI!AA186 -> 0 | E4: =DERS_PLANI!AA198 -> 0 | F4: =DERS_PLANI!AA210 -> 0
A5: 10.50 - 11.40 | B5: =DERS_PLANI!AA163 -> 0 | C5: =DERS_PLANI!AA175 -> 0 | D5: =DERS_PLANI!AA187 -> 0 | E5: =DERS_PLANI!AA199 -> 0 | F5: =DERS_PLANI!AA211 -> 0
A6: 12.20 - 13.10 | B6: =DERS_PLANI!AA164 -> 0 | C6: =DERS_PLANI!AA176 -> 0 | D6: =DERS_PLANI!AA188 -> 0 | E6: =DERS_PLANI!AA200 -> 0 | F6: =DERS_PLANI!AA212 -> 0
A7: 13.15 - 14.05 | B7: =DERS_PLANI!AA165 -> 0 | C7: =DERS_PLANI!AA177 -> 0 | D7: =DERS_PLANI!AA189 -> 0 | E7: =DERS_PLANI!AA201 -> 0 | F7: =DERS_PLANI!AA213 -> 0
A8: 14.10 - 15.00 | B8: =DERS_PLANI!AA166 -> 0 | C8: =DERS_PLANI!AA178 -> 0 | D8: =DERS_PLANI!AA190 -> 0 | E8: =DERS_PLANI!AA202 -> 0 | F8: =DERS_PLANI!AA214 -> 0
A9: 15.20 - 16.10 | B9: =DERS_PLANI!AA167 -> 0 | C9: =DERS_PLANI!AA179 -> 0 | D9: =DERS_PLANI!AA191 -> 0 | E9: =DERS_PLANI!AA203 -> 0 | F9: =DERS_PLANI!AA215 -> 0
A10: 16.15 - 17.05 | B10: =DERS_PLANI!AA168 -> 0 | C10: =DERS_PLANI!AA180 -> 0 | D10: =DERS_PLANI!AA192 -> 0 | E10: =DERS_PLANI!AA204 -> 0 | F10: =DERS_PLANI!AA216 -> 0
A11: 17.10 - 18.00 | B11: =DERS_PLANI!AA169 -> 0 | C11: =DERS_PLANI!AA181 -> 0 | D11: =DERS_PLANI!AA193 -> 0 | E11: =DERS_PLANI!AA205 -> 0 | F11: =DERS_PLANI!AA217 -> 0
A12: 18:10 -19:00 | B12: =DERS_PLANI!AA170 -> 0 | C12: =DERS_PLANI!AA182 -> 0 | D12: =DERS_PLANI!AA194 -> 0 | E12: =DERS_PLANI!AA206 -> 0 | F12: =DERS_PLANI!AA218 -> 0
A13: 19:10 - 20:00 | B13: =DERS_PLANI!AA171 -> 0 | C13: =DERS_PLANI!AA183 -> 0 | D13: =DERS_PLANI!AA195 -> 0 | E13: =DERS_PLANI!AA207 -> 0 | F13: =DERS_PLANI!AA219 -> 0
A14: 20:10 - 21:00 | B14: =DERS_PLANI!AA172 -> 0 | C14: =DERS_PLANI!AA184 -> 0 | D14: =DERS_PLANI!AA196 -> 0 | E14: =DERS_PLANI!AA208 -> 0 | F14: =DERS_PLANI!AA220 -> 0

Sheet LECTURE HALL 7
A1: LECTURE HALL 7
A2: Saat/Gün | B2: Pazartesi | C2: Salı | D2: Çarşamba | E2: Perşembe | F2: Cuma
A3: 09.00 - 09.50 | B3: =DERS_PLANI!AB161 -> 0 | C3: =DERS_PLANI!AB173 -> 0 | D3: =DERS_PLANI!AB185 -> 0 | E3: =DERS_PLANI!AB197 -> 0 | F3: =DERS_PLANI!AB209 -> PSY Telafi Sınavları
A4: 09.55 - 10.45 | B4: =DERS_PLANI!AB162 -> 0 | C4: =DERS_PLANI!AB174 -> 0 | D4: =DERS_PLANI!AB186 -> 0 | E4: =DERS_PLANI!AB198 -> 0 | F4: =DERS_PLANI!AB210 -> PSY Telafi Sınavları
A5: 10.50 - 11.40 | B5: =DERS_PLANI!AB163 -> 0 | C5: =DERS_PLANI!AB175 -> 0 | D5: =DERS_PLANI!AB187 -> 0 | E5: =DERS_PLANI!AB199 -> 0 | F5: =DERS_PLANI!AB211 -> PSY Telafi Sınavları
A6: 12.20 - 13.10 | B6: =DERS_PLANI!AB164 -> 0 | C6: =DERS_PLANI!AB176 -> PSİ 479 | D6: =DERS_PLANI!AB188 -> 0 | E6: =DERS_PLANI!AB200 -> 0 | F6: =DERS_PLANI!AB212 -> 0
A7: 13.15 - 14.05 | B7: =DERS_PLANI!AB165 -> 0 | C7: =DERS_PLANI!AB177 -> PSİ 479 | D7: =DERS_PLANI!AB189 -> 0 | E7: =DERS_PLANI!AB201 -> 0 | F7: =DERS_PLANI!AB213 -> 0
A8: 14.10 - 15.00 | B8: =DERS_PLANI!AB166 -> 0 | C8: =DERS_PLANI!AB178 -> PSİ 479 | D8: =DERS_PLANI!AB190 -> 0 | E8: =DERS_PLANI!AB202 -> 0 | F8: =DERS_PLANI!AB214 -> 0
A9: 15.20 - 16.10 | B9: =DERS_PLANI!AB167 -> 0 | C9: =DERS_PLANI!AB179 -> 0 | D9: =DERS_PLANI!AB191 -> 0 | E9: =DERS_PLANI!AB203 -> 0 | F9: =DERS_PLANI!AB215 -> 0
A10: 16.15 - 17.05 | B10: =DERS_PLANI!AB168 -> 0 | C10: =DERS_PLANI!AB180 -> 0 | D10: =DERS_PLANI!AB192 -> 0 | E10: =DERS_PLANI!AB204 -> 0 | F10: =DERS_PLANI!AB216 -> 0
A11: 17.10 - 18.00 | B11: =DERS_PLANI!AB169 -> 0 | C11: =DERS_PLANI!AB181 -> 0 | D11: =DERS_PLANI!AB193 -> 0 | E11: =DERS_PLANI!AB205 -> 0 | F11: =DERS_PLANI!AB217 -> 0
A12: 18:10 -19:00 | B12: =DERS_PLANI!AB170 -> 0 | C12: =DERS_PLANI!AB182 -> 0 | D12: =DERS_PLANI!AB194 -> 0 | E12: =DERS_PLANI!AB206 -> 0 | F12: =DERS_PLANI!AB218 -> 0
A13: 19:10 - 20:00 | B13: =DERS_PLANI!AB171 -> 0 | C13: =DERS_PLANI!AB183 -> 0 | D13: =DERS_PLANI!AB195 -> 0 | E13: =DERS_PLANI!AB207 -> 0 | F13: =DERS_PLANI!AB219 -> 0
A14: 20:10 - 21:00 | B14: =DERS_PLANI!AB172 -> 0 | C14: =DERS_PLANI!AB184 -> 0 | D14: =DERS_PLANI!AB196 -> 0 | E14: =DERS_PLANI!AB208 -> 0 | F14: =DERS_PLANI!AB220 -> 0

Sheet C 092
A1: C 092
A2: Saat/Gün | B2: Pazartesi | C2: Salı | D2: Çarşamba | E2: Perşembe | F2: Cuma
A3: 09.00 - 09.50 | B3: =DERS_PLANI!AV161 -> 0 | C3: =DERS_PLANI!AV173 -> 0 | D3: =DERS_PLANI!AV185 -> 0 | E3: =DERS_PLANI!AV197 -> 0 | F3: =DERS_PLANI!AV209 -> 0
A4: 09.55 - 10.45 | B4: =DERS_PLANI!AV162 -> 0 | C4: =DERS_PLANI!AV174 -> 0 | D4: =DERS_PLANI!AV186 -> 0 | E4: =DERS_PLANI!AV198 -> 0 | F4: =DERS_PLANI!AV210 -> 0
A5: 10.50 - 11.40 | B5: =DERS_PLANI!AV163 -> 0 | C5: =DERS_PLANI!AV175 -> 0 | D5: =DERS_PLANI!AV187 -> 0 | E5: =DERS_PLANI!AV199 -> 0 | F5: =DERS_PLANI!AV211 -> 0
A6: 12.20 - 13.10 | B6: =DERS_PLANI!AV164 -> 0 | C6: =DERS_PLANI!AV176 -> 0 | D6: =DERS_PLANI!AV188 -> 0 | E6: =DERS_PLANI!AV200 -> 0 | F6: =DERS_PLANI!AV212 -> 0
A7: 13.15 - 14.05 | B7: =DERS_PLANI!AV165 -> 0 | C7: =DERS_PLANI!AV177 -> 0 | D7: =DERS_PLANI!AV189 -> 0 | E7: =DERS_PLANI!AV201 -> 0 | F7: =DERS_PLANI!AV213 -> 0
A8: 14.10 - 15.00 | B8: =DERS_PLANI!AV166 -> 0 | C8: =DERS_PLANI!AV178 -> 0 | D8: =DERS_PLANI!AV190 -> 0 | E8: =DERS_PLANI!AV202 -> 0 | F8: =DERS_PLANI!AV214 -> 0
A9: 15.20 - 16.10 | B9: =DERS_PLANI!AV167 -> 0 | C9: =DERS_PLANI!AV179 -> 0 | D9: =DERS_PLANI!AV191 -> 0 | E9: =DERS_PLANI!AV203 -> 0 | F9: =DERS_PLANI!AV215 -> 0
A10: 16.15 - 17.05 | B10: =DERS_PLANI!AV168 -> 0 | C10: =DERS_PLANI!AV180 -> 0 | D10: =DERS_PLANI!AV192 -> 0 | E10: =DERS_PLANI!AV204 -> 0 | F10: =DERS_PLANI!AV216 -> 0
A11: 17.10 - 18.00 | B11: =DERS_PLANI!AV169 -> 0 | C11: =DERS_PLANI!AV181 -> 0 | D11: =DERS_PLANI!AV193 -> 0 | E11: =DERS_PLANI!AV205 -> 0 | F11: =DERS_PLANI!AV217 -> 0
A12: 18:10 -19:00 | B12: =DERS_PLANI!AV170 -> 0 | C12: =DERS_PLANI!AV182 -> 0 | D12: =DERS_PLANI!AV194 -> 0 | E12: =DERS_PLANI!AV206 -> 0 | F12: =DERS_PLANI!AV218 -> 0
A13: 19:10 - 20:00 | B13: =DERS_PLANI!AV171 -> 0 | C13: =DERS_PLANI!AV183 -> 0 | D13: =DERS_PLANI!AV195 -> 0 | E13: =DERS_PLANI!AV207 -> 0 | F13: =DERS_PLANI!AV219 -> 0
A14: 20:10 - 21:00 | B14: =DERS_PLANI!AV172 -> 0 | C14: =DERS_PLANI!AV184 -> 0 | D14: =DERS_PLANI!AV196 -> 0 | E14: =DERS_PLANI!AV208 -> 0 | F14: =DERS_PLANI!AV220 -> 0

Sheet C 091
A1: C 091
A2: Saat/Gün | B2: Pazartesi | C2: Salı | D2: Çarşamba | E2: Perşembe | F2: Cuma
A3: 09.00 - 09.50 | B3: =DERS_PLANI!AU161 -> 0 | C3: =DERS_PLANI!AU173 -> 0 | D3: =DERS_PLANI!AU185 -> 0 | E3: =DERS_PLANI!AU197 -> 0 | F3: =DERS_PLANI!AV197 -> 0
A4: 09.55 - 10.45 | B4: =DERS_PLANI!AU162 -> 0 | C4: =DERS_PLANI!AU174 -> 0 | D4: =DERS_PLANI!AU186 -> 0 | E4: =DERS_PLANI!AU198 -> 0 | F4: =DERS_PLANI!AV198 -> 0
A5: 10.50 - 11.40 | B5: =DERS_PLANI!AU163 -> 0 | C5: =DERS_PLANI!AU175 -> 0 | D5: =DERS_PLANI!AU187 -> 0 | E5: =DERS_PLANI!AU199 -> 0 | F5: =DERS_PLANI!AV199 -> 0
A6: 12.20 - 13.10 | B6: =DERS_PLANI!AU164 -> 0 | C6: =DERS_PLANI!AU176 -> 0 | D6: =DERS_PLANI!AU188 -> 0 | E6: =DERS_PLANI!AU200 -> 0 | F6: =DERS_PLANI!AV200 -> 0
A7: 13.15 - 14.05 | B7: =DERS_PLANI!AU165 -> 0 | C7: =DERS_PLANI!AU177 -> 0 | D7: =DERS_PLANI!AU189 -> 0 | E7: =DERS_PLANI!AU201 -> 0 | F7: =DERS_PLANI!AV201 -> 0
A8: 14.10 - 15.00 | B8: =DERS_PLANI!AU166 -> 0 | C8: =DERS_PLANI!AU178 -> 0 | D8: =DERS_PLANI!AU190 -> 0 | E8: =DERS_PLANI!AU202 -> 0 | F8: =DERS_PLANI!AV202 -> 0
A9: 15.20 - 16.10 | B9: =DERS_PLANI!AU167 -> 0 | C9: =DERS_PLANI!AU179 -> 0 | D9: =DERS_PLANI!AU191 -> 0 | E9: =DERS_PLANI!AU203 -> 0 | F9: =DERS_PLANI!AV203 -> 0
A10: 16.15 - 17.05 | B10: =DERS_PLANI!AU168 -> 0 | C10: =DERS_PLANI!AU180 -> 0 | D10: =DERS_PLANI!AU192 -> 0 | E10: =DERS_PLANI!AU204 -> 0 | F10: =DERS_PLANI!AV204 -> 0
A11: 17.10 - 18.00 | B11: =DERS_PLANI!AU169 -> 0 | C11: =DERS_PLANI!AU181 -> 0 | D11: =DERS_PLANI!AU193 -> 0 | E11: =DERS_PLANI!AU205 -> 0 | F11: =DERS_PLANI!AV205 -> 0
A12: 18:10 -19:00 | B12: =DERS_PLANI!AU170 -> 0 | C12: =DERS_PLANI!AU182 -> 0 | D12: =DERS_PLANI!AU194 -> 0 | E12: =DERS_PLANI!AU206 -> 0 | F12: =DERS_PLANI!AV206 -> 0
A13: 19:10 - 20:00 | B13: =DERS_PLANI!AU171 -> 0 | C13: =DERS_PLANI!AU183 -> 0 | D13: =DERS_PLANI!AU195 -> 0 | E13: =DERS_PLANI!AU207 -> 0 | F13: =DERS_PLANI!AV207 -> 0
A14: 20:10 - 21:00 | B14: =DERS_PLANI!AU172 -> 0 | C14: =DERS_PLANI!AU184 -> 0 | D14: =DERS_PLANI!AU196 -> 0 | E14: =DERS_PLANI!AU208 -> 0 | F14: =DERS_PLANI!AV208 -> 0

Sheet C 090
A1: C 090
A2: Saat/Gün | B2: Pazartesi | C2: Salı | D2: Çarşamba | E2: Perşembe | F2: Cuma
A3: 09.00 - 09.50 | B3: =DERS_PLANI!AT161 -> MYO - BIL 211 BİLGİSAYARLI İSTATİSTİK Ş1 | C3: =DERS_PLANI!AT173 -> MYO - IHA106 BİLGİSAYAR DESTEKLİ TASARIM ş1 | D3: =DERS_PLANI!AT185 -> MYO - BIL208 MOBİL PROGRAMLAMA ş1 | E3: =DERS_PLANI!AT197 -> MYO - BIL210 VERİ YAPILARI Ş1 | F3: =DERS_PLANI!AT209 -> MYO - TAP 104 BİLGİSAYAR DESTEKLİ TASARIM II Ş3
A4: 09.55 - 10.45 | B4: =DERS_PLANI!AT162 -> MYO - BIL 211 BİLGİSAYARLI İSTATİSTİK Ş1 | C4: =DERS_PLANI!AT174 -> MYO - IHA106 BİLGİSAYAR DESTEKLİ TASARIM ş1 | D4: =DERS_PLANI!AT186 -> MYO - BIL208 MOBİL PROGRAMLAMA ş1 | E4: =DERS_PLANI!AT198 -> MYO - BIL210 VERİ YAPILARI Ş1 | F4: =DERS_PLANI!AT210 -> MYO - TAP 104 BİLGİSAYAR DESTEKLİ TASARIM II Ş3
A5: 10.50 - 11.40 | B5: =DERS_PLANI!AT163 -> MYO - BIL 211 BİLGİSAYARLI İSTATİSTİK Ş1 | C5: =DERS_PLANI!AT175 -> MYO - IHA106 BİLGİSAYAR DESTEKLİ TASARIM ş1 | D5: =DERS_PLANI!AT187 -> MYO - BIL208 MOBİL PROGRAMLAMA ş1 | E5: =DERS_PLANI!AT199 -> MYO - BIL210 VERİ YAPILARI Ş1 | F5: =DERS_PLANI!AT211 -> MYO - TAP 104 BİLGİSAYAR DESTEKLİ TASARIM II Ş3
A6: 12.20 - 13.10 | B6: =DERS_PLANI!AT164 -> MYO -TAP 108 DİJİTAL TASARIM Ş1 | C6: =DERS_PLANI!AT176 -> TAP 204 BİLGİSAYAR DESTEKLİ ANİMASYON II Ş1 | D6: =DERS_PLANI!AT188 -> MYO - BGT 108 WEB GÜVENLİĞİ ş1 | E6: =DERS_PLANI!AT200 -> MYO - BGT 108 WEB GÜVENLİĞİ ş2 | F6: =DERS_PLANI!AT212 -> 0
A7: 13.15 - 14.05 | B7: =DERS_PLANI!AT165 -> MYO -TAP 108 DİJİTAL TASARIM Ş1 | C7: =DERS_PLANI!AT177 -> TAP 204 BİLGİSAYAR DESTEKLİ ANİMASYON II Ş1 | D7: =DERS_PLANI!AT189 -> MYO - BGT 108 WEB GÜVENLİĞİ ş1 | E7: =DERS_PLANI!AT201 -> MYO - BGT 108 WEB GÜVENLİĞİ ş2 | F7: =DERS_PLANI!AT213 -> 0
A8: 14.10 - 15.00 | B8: =DERS_PLANI!AT166 -> MYO -TAP 108 DİJİTAL TASARIM Ş1 | C8: =DERS_PLANI!AT178 -> TAP 204 BİLGİSAYAR DESTEKLİ ANİMASYON II Ş1 | D8: =DERS_PLANI!AT190 -> MYO - BGT 108 WEB GÜVENLİĞİ ş1 | E8: =DERS_PLANI!AT202 -> MYO - BGT 108 WEB GÜVENLİĞİ ş2 | F8: =DERS_PLANI!AT214 -> 0
A9: 15.20 - 16.10 | B9: =DERS_PLANI!AT167 -> MYO -TAP 108 DİJİTAL TASARIM Ş2 | C9: =DERS_PLANI!AT179 -> TAP 204 BİLGİSAYAR DESTEKLİ ANİMASYON II Ş2 | D9: =DERS_PLANI!AT191 -> MYO - BIL208 MOBİL PROGRAMLAMA ş2 | E9: =DERS_PLANI!AT203 -> MYO - VTK 104 Web Okuryazarlığı | F9: =DERS_PLANI!AT215 -> 0
A10: 16.15 - 17.05 | B10: =DERS_PLANI!AT168 -> MYO -TAP 108 DİJİTAL TASARIM Ş2 | C10: =DERS_PLANI!AT180 -> TAP 204 BİLGİSAYAR DESTEKLİ ANİMASYON II Ş2 | D10: =DERS_PLANI!AT192 -> MYO - BIL208 MOBİL PROGRAMLAMA ş2 | E10: =DERS_PLANI!AT204 -> MYO - VTK 104 Web Okuryazarlığı | F10: =DERS_PLANI!AT216 -> 0
A11: 17.10 - 18.00 | B11: =DERS_PLANI!AT169 -> MYO -TAP 108 DİJİTAL TASARIM Ş2 | C11: =DERS_PLANI!AT181 -> TAP 204 BİLGİSAYAR DESTEKLİ ANİMASYON II Ş2 | D11: =DERS_PLANI!AT193 -> MYO - BIL208 MOBİL PROGRAMLAMA ş2 | E11: =DERS_PLANI!AT205 -> MYO - VTK 104 Web Okuryazarlığı | F11: =DERS_PLANI!AT217 -> 0
A12: 18:10 -19:00 | B12: =DERS_PLANI!AT170 -> 0 | C12: =DERS_PLANI!AT182 -> 0 | D12: =DERS_PLANI!AT194 -> 0 | E12: =DERS_PLANI!AT206 -> 0 | F12: =DERS_PLANI!AT218 -> 0
A13: 19:10 - 20:00 | B13: =DERS_PLANI!AT171 -> 0 | C13: =DERS_PLANI!AT183 -> 0 | D13: =DERS_PLANI!AT195 -> 0 | E13: =DERS_PLANI!AT207 -> 0 | F13: =DERS_PLANI!AT219 -> 0
A14: 20:10 - 21:00 | B14: =DERS_PLANI!AT172 -> 0 | C14: =DERS_PLANI!AT184 -> 0 | D14: =DERS_PLANI!AT196 -> 0 | E14: =DERS_PLANI!AT208 -> 0 | F14: =DERS_PLANI!AT220 -> 0

Sheet C 089
A1: C 089
A2: Saat/Gün | B2: Pazartesi | C2: Salı | D2: Çarşamba | E2: Perşembe | F2: Cuma
A3: 09.00 - 09.50 | B3: =DERS_PLANI!AS161 -> MYO - BIL 215 Nesne Tabanli Programlama II Ş1 | C3: =DERS_PLANI!AS173 -> MYO - VTK 108 İleri Web Tasarımı | D3: =DERS_PLANI!AS185 -> MYO - IHA106 BİLGİSAYAR DESTEKLİ TASARIM ş2 | E3: =DERS_PLANI!AS197 -> MYO - TAP 102 GRAFİK VE ANİMASYON Ş1 | F3: =DERS_PLANI!AS209 -> MYO - BIL 201 Görsel Programlama II Ş2
A4: 09.55 - 10.45 | B4: =DERS_PLANI!AS162 -> MYO - BIL 215 Nesne Tabanli Programlama II Ş1 | C4: =DERS_PLANI!AS174 -> MYO - VTK 108 İleri Web Tasarımı | D4: =DERS_PLANI!AS186 -> MYO - IHA106 BİLGİSAYAR DESTEKLİ TASARIM ş2 | E4: =DERS_PLANI!AS198 -> MYO - TAP 102 GRAFİK VE ANİMASYON Ş1 | F4: =DERS_PLANI!AS210 -> MYO - BIL 201 Görsel Programlama II Ş2
A5: 10.50 - 11.40 | B5: =DERS_PLANI!AS163 -> MYO - BIL 215 Nesne Tabanli Programlama II Ş1 | C5: =DERS_PLANI!AS175 -> MYO - VTK 108 İleri Web Tasarımı | D5: =DERS_PLANI!AS187 -> MYO - IHA106 BİLGİSAYAR DESTEKLİ TASARIM ş2 | E5: =DERS_PLANI!AS199 -> MYO - TAP 102 GRAFİK VE ANİMASYON Ş1 | F5: =DERS_PLANI!AS211 -> MYO - BIL 201 Görsel Programlama II Ş2
A6: 12.20 - 13.10 | B6: =DERS_PLANI!AS164 -> MYO - TAP 104 BİLGİSAYAR DESTEKLİ TASARIM II Ş1 | C6: =DERS_PLANI!AS176 -> MYO - TAP 208 İLLUSTRASYON Ş1 | D6: =DERS_PLANI!AS188 -> MYO - BGT 102 GÜVENLİ AĞ TASARIMI VE CİHAZ YÖNETİMİ ş2 | E6: =DERS_PLANI!AS200 -> MYO - TAP 102 GRAFİK VE ANİMASYON Ş2 | F6: =DERS_PLANI!AS212 -> 0
A7: 13.15 - 14.05 | B7: =DERS_PLANI!AS165 -> MYO - TAP 104 BİLGİSAYAR DESTEKLİ TASARIM II Ş1 | C7: =DERS_PLANI!AS177 -> MYO - TAP 208 İLLUSTRASYON Ş1 | D7: =DERS_PLANI!AS189 -> MYO - BGT 102 GÜVENLİ AĞ TASARIMI VE CİHAZ YÖNETİMİ ş2 | E7: =DERS_PLANI!AS201 -> MYO - TAP 102 GRAFİK VE ANİMASYON Ş2 | F7: =DERS_PLANI!AS213 -> 0
A8: 14.10 - 15.00 | B8: =DERS_PLANI!AS166 -> MYO - TAP 104 BİLGİSAYAR DESTEKLİ TASARIM II Ş1 | C8: =DERS_PLANI!AS178 -> MYO - TAP 208 İLLUSTRASYON Ş1 | D8: =DERS_PLANI!AS190 -> MYO - BGT 102 GÜVENLİ AĞ TASARIMI VE CİHAZ YÖNETİMİ ş2 | E8: =DERS_PLANI!AS202 -> MYO - TAP 102 GRAFİK VE ANİMASYON Ş2 | F8: =DERS_PLANI!AS214 -> 0
A9: 15.20 - 16.10 | B9: =DERS_PLANI!AS167 -> MYO - TAP 104 BİLGİSAYAR DESTEKLİ TASARIM II Ş2 | C9: =DERS_PLANI!AS179 -> MYO - TAP 208 İLLUSTRASYON Ş2 | D9: =DERS_PLANI!AS191 -> CMM152 | E9: =DERS_PLANI!AS203 -> MYO - BIL 201 Görsel Programlama II Ş1 | F9: =DERS_PLANI!AS215 -> 0
A10: 16.15 - 17.05 | B10: =DERS_PLANI!AS168 -> MYO - TAP 104 BİLGİSAYAR DESTEKLİ TASARIM II Ş2 | C10: =DERS_PLANI!AS180 -> MYO - TAP 208 İLLUSTRASYON Ş2 | D10: =DERS_PLANI!AS192 -> CMM152 | E10: =DERS_PLANI!AS204 -> MYO - BIL 201 Görsel Programlama II Ş1 | F10: =DERS_PLANI!AS216 -> 0
A11: 17.10 - 18.00 | B11: =DERS_PLANI!AS169 -> MYO - TAP 104 BİLGİSAYAR DESTEKLİ TASARIM II Ş2 | C11: =DERS_PLANI!AS181 -> MYO - TAP 208 İLLUSTRASYON Ş2 | D11: =DERS_PLANI!AS193 -> CMM152 | E11: =DERS_PLANI!AS205 -> MYO - BIL 201 Görsel Programlama II Ş1 | F11: =DERS_PLANI!AS217 -> 0
A12: 18:10 -19:00 | B12: =DERS_PLANI!AS170 -> 0 | C12: =DERS_PLANI!AS182 -> 0 | D12: =DERS_PLANI!AS194 -> 0 | E12: =DERS_PLANI!AS206 -> 0 | F12: =DERS_PLANI!AS218 -> 0
A13: 19:10 - 20:00 | B13: =DERS_PLANI!AS171 -> 0 | C13: =DERS_PLANI!AS183 -> 0 | D13: =DERS_PLANI!AS195 -> 0 | E13: =DERS_PLANI!AS207 -> 0 | F13: =DERS_PLANI!AS219 -> 0
A14: 20:10 - 21:00 | B14: =DERS_PLANI!AS172 -> 0 | C14: =DERS_PLANI!AS184 -> 0 | D14: =DERS_PLANI!AS196 -> 0 | E14: =DERS_PLANI!AS208 -> 0 | F14: =DERS_PLANI!AS220 -> 0

Sheet C 088
A1: C 088
A2: Saat/Gün | B2: Pazartesi | C2: Salı | D2: Çarşamba | E2: Perşembe | F2: Cuma
A3: 09.00 - 09.50 | B3: =DERS_PLANI!AR161 -> ENG 202 - 08 - GSTF | C3: =DERS_PLANI!AR173 -> 0 | D3: =DERS_PLANI!AR185 -> 0 | E3: =DERS_PLANI!AR197 -> IAD 242 | F3: =DERS_PLANI!AR209 -> CMM 371 Freehand Drawing and Rendering Techniques
A4: 09.55 - 10.45 | B4: =DERS_PLANI!AR162 -> ENG 202 - 08 - GSTF | C4: =DERS_PLANI!AR174 -> 0 | D4: =DERS_PLANI!AR186 -> 0 | E4: =DERS_PLANI!AR198 -> IAD 242 | F4: =DERS_PLANI!AR210 -> CMM 371 Freehand Drawing and Rendering Techniques
A5: 10.50 - 11.40 | B5: =DERS_PLANI!AR163 -> 0 | C5: =DERS_PLANI!AR175 -> 0 | D5: =DERS_PLANI!AR187 -> 0 | E5: =DERS_PLANI!AR199 -> IAD 242 | F5: =DERS_PLANI!AR211 -> CMM 371 Freehand Drawing and Rendering Techniques
A6: 12.20 - 13.10 | B6: =DERS_PLANI!AR164 -> 0 | C6: =DERS_PLANI!AR176 -> 0 | D6: =DERS_PLANI!AR188 -> 0 | E6: =DERS_PLANI!AR200 -> 0 | F6: =DERS_PLANI!AR212 -> 0
A7: 13.15 - 14.05 | B7: =DERS_PLANI!AR165 -> IAD 101 | C7: =DERS_PLANI!AR177 -> IAD 351 (Dr. Nihan Türker) | D7: =DERS_PLANI!AR189 -> 0 | E7: =DERS_PLANI!AR201 -> IAD 101 | F7: =DERS_PLANI!AR213 -> 0
A8: 14.10 - 15.00 | B8: =DERS_PLANI!AR166 -> IAD 101 | C8: =DERS_PLANI!AR178 -> IAD 351 (Dr. Nihan Türker) | D8: =DERS_PLANI!AR190 -> 0 | E8: =DERS_PLANI!AR202 -> IAD 101 | F8: =DERS_PLANI!AR214 -> 0
A9: 15.20 - 16.10 | B9: =DERS_PLANI!AR167 -> IAD 101 | C9: =DERS_PLANI!AR179 -> IAD 351 (Dr. Nihan Türker) | D9: =DERS_PLANI!AR191 -> 0 | E9: =DERS_PLANI!AR203 -> IAD 101 | F9: =DERS_PLANI!AR215 -> 0
A10: 16.15 - 17.05 | B10: =DERS_PLANI!AR168 -> IAD 101 | C10: =DERS_PLANI!AR180 -> IAD 351 (Dr. Nihan Türker) | D10: =DERS_PLANI!AR192 -> 0 | E10: =DERS_PLANI!AR204 -> IAD 101 | F10: =DERS_PLANI!AR216 -> 0
A11: 17.10 - 18.00 | B11: =DERS_PLANI!AR169 -> 0 | C11: =DERS_PLANI!AR181 -> IAD 351 (Dr. Nihan Türker) | D11: =DERS_PLANI!AR193 -> 0 | E11: =DERS_PLANI!AR205 -> 0 | F11: =DERS_PLANI!AR217 -> 0
A12: 18:10 -19:00 | B12: =DERS_PLANI!AR170 -> 0 | C12: =DERS_PLANI!AR182 -> 0 | D12: =DERS_PLANI!AR194 -> 0 | E12: =DERS_PLANI!AR206 -> 0 | F12: =DERS_PLANI!AR218 -> 0
A13: 19:10 - 20:00 | B13: =DERS_PLANI!AR171 -> 0 | C13: =DERS_PLANI!AR183 -> 0 | D13: =DERS_PLANI!AR195 -> 0 | E13: =DERS_PLANI!AR207 -> 0 | F13: =DERS_PLANI!AR219 -> 0
A14: 20:10 - 21:00 | B14: =DERS_PLANI!AR172 -> 0 | C14: =DERS_PLANI!AR184 -> 0 | D14: =DERS_PLANI!AR196 -> 0 | E14: =DERS_PLANI!AR208 -> 0 | F14: =DERS_PLANI!AR220 -> 0

Sheet C 087
A1: C 087
A2: Saat/Gün | B2: Pazartesi | C2: Salı | D2: Çarşamba | E2: Perşembe | F2: Cuma
A3: 09.00 - 09.50 | B3: =DERS_PLANI!AQ161 -> 0 | C3: =DERS_PLANI!AQ173 -> 0 | D3: =DERS_PLANI!AQ185 -> 0 | E3: =DERS_PLANI!AQ197 -> ceng214 - algoritma II | F3: =DERS_PLANI!AQ209 -> 0
A4: 09.55 - 10.45 | B4: =DERS_PLANI!AQ162 -> 0 | C4: =DERS_PLANI!AQ174 -> 0 | D4: =DERS_PLANI!AQ186 -> 0 | E4: =DERS_PLANI!AQ198 -> ceng214 - algoritma II | F4: =DERS_PLANI!AQ210 -> 0
A5: 10.50 - 11.40 | B5: =DERS_PLANI!AQ163 -> 0 | C5: =DERS_PLANI!AQ175 -> 0 | D5: =DERS_PLANI!AQ187 -> 0 | E5: =DERS_PLANI!AQ199 -> ceng214 - algoritma II | F5: =DERS_PLANI!AQ211 -> 0
A6: 12.20 - 13.10 | B6: =DERS_PLANI!AQ164 -> 0 | C6: =DERS_PLANI!AQ176 -> 0 | D6: =DERS_PLANI!AQ188 -> MIS 242 (Assoc. Prof. Erdoğan) | E6: =DERS_PLANI!AQ200 -> YBS 372 - PROGRAMLAMADA ÖZEL KONULAR CEM IRMAK | F6: =DERS_PLANI!AQ212 -> 0
A7: 13.15 - 14.05 | B7: =DERS_PLANI!AQ165 -> 0 | C7: =DERS_PLANI!AQ177 -> ENG 302 - 8 | D7: =DERS_PLANI!AQ189 -> MIS 242 (Assoc. Prof. Erdoğan) | E7: =DERS_PLANI!AQ201 -> YBS 372 - PROGRAMLAMADA ÖZEL KONULAR CEM IRMAK | F7: =DERS_PLANI!AQ213 -> 0
A8: 14.10 - 15.00 | B8: =DERS_PLANI!AQ166 -> 0 | C8: =DERS_PLANI!AQ178 -> ENG 302 - 8 | D8: =DERS_PLANI!AQ190 -> MIS 242 (Assoc. Prof. Erdoğan) | E8: =DERS_PLANI!AQ202 -> YBS 372 - PROGRAMLAMADA ÖZEL KONULAR CEM IRMAK | F8: =DERS_PLANI!AQ214 -> 0
A9: 15.20 - 16.10 | B9: =DERS_PLANI!AQ167 -> 0 | C9: =DERS_PLANI!AQ179 -> 0 | D9: =DERS_PLANI!AQ191 -> 0 | E9: =DERS_PLANI!AQ203 -> 0 | F9: =DERS_PLANI!AQ215 -> 0
A10: 16.15 - 17.05 | B10: =DERS_PLANI!AQ168 -> 0 | C10: =DERS_PLANI!AQ180 -> 0 | D10: =DERS_PLANI!AQ192 -> 0 | E10: =DERS_PLANI!AQ204 -> 0 | F10: =DERS_PLANI!AQ216 -> 0
A11: 17.10 - 18.00 | B11: =DERS_PLANI!AQ169 -> 0 | C11: =DERS_PLANI!AQ181 -> 0 | D11: =DERS_PLANI!AQ193 -> 0 | E11: =DERS_PLANI!AQ205 -> 0 | F11: =DERS_PLANI!AQ217 -> 0
A12: 18:10 -19:00 | B12: =DERS_PLANI!AQ170 -> 0 | C12: =DERS_PLANI!AQ182 -> 0 | D12: =DERS_PLANI!AQ194 -> 0 | E12: =DERS_PLANI!AQ206 -> 0 | F12: =DERS_PLANI!AQ218 -> 0
A13: 19:10 - 20:00 | B13: =DERS_PLANI!AQ171 -> 0 | C13: =DERS_PLANI!AQ183 -> 0 | D13: =DERS_PLANI!AQ195 -> 0 | E13: =DERS_PLANI!AQ207 -> 0 | F13: =DERS_PLANI!AQ219 -> 0
A14: 20:10 - 21:00 | B14: =DERS_PLANI!AQ172 -> 0 | C14: =DERS_PLANI!AQ184 -> 0 | D14: =DERS_PLANI!AQ196 -> 0 | E14: =DERS_PLANI!AQ208 -> 0 | F14: =DERS_PLANI!AQ220 -> 0

Sheet C 086
A1: C 086
A2: Saat/Gün | B2: Pazartesi | C2: Salı | D2: Çarşamba | E2: Perşembe | F2: Cuma
A3: 09.00 - 09.50 | B3: =DERS_PLANI!AP161 -> MYO - ETP224 Pazarlamada Vaka Analizleri | C3: =DERS_PLANI!AP173 -> 0 | D3: =DERS_PLANI!AP185 -> MYO - TAP 202 SİNEMA VE ANİMASYON TARİHİ | E3: =DERS_PLANI!AP197 -> MYO - IHA 231 METEOROLOJİ | F3: =DERS_PLANI!AP209 -> 0
A4: 09.55 - 10.45 | B4: =DERS_PLANI!AP162 -> MYO - ETP224 Pazarlamada Vaka Analizleri | C4: =DERS_PLANI!AP174 -> MYO - TAP 210 FİKRİ HAKLAR VE ETİK | D4: =DERS_PLANI!AP186 -> MYO - TAP 202 SİNEMA VE ANİMASYON TARİHİ | E4: =DERS_PLANI!AP198 -> MYO - IHA 231 METEOROLOJİ | F4: =DERS_PLANI!AP210 -> 0
A5: 10.50 - 11.40 | B5: =DERS_PLANI!AP163 -> MYO - ETP224 Pazarlamada Vaka Analizleri | C5: =DERS_PLANI!AP175 -> MYO - TAP 210 FİKRİ HAKLAR VE ETİK | D5: =DERS_PLANI!AP187 -> MYO - TAP 202 SİNEMA VE ANİMASYON TARİHİ | E5: =DERS_PLANI!AP199 -> MYO - IHA 231 METEOROLOJİ | F5: =DERS_PLANI!AP211 -> 0
A6: 12.20 - 13.10 | B6: =DERS_PLANI!AP164 -> MYO - ETP 206 DIŞ TİCARET İŞLEMLERİ YÖNETİMİ | C6: =DERS_PLANI!AP176 -> MYO - TAP 206 YARATICI YAZARLIK | D6: =DERS_PLANI!AP188 -> MYO - TAP 228 Sanat Tarihi | E6: =DERS_PLANI!AP200 -> MYO - TAP 206 YARATICI YAZARLIK | F6: =DERS_PLANI!AP212 -> 0
A7: 13.15 - 14.05 | B7: =DERS_PLANI!AP165 -> MYO - ETP 206 DIŞ TİCARET İŞLEMLERİ YÖNETİMİ | C7: =DERS_PLANI!AP177 -> MYO - TAP 206 YARATICI YAZARLIK | D7: =DERS_PLANI!AP189 -> MYO - TAP 228 Sanat Tarihi | E7: =DERS_PLANI!AP201 -> MYO - TAP 206 YARATICI YAZARLIK | F7: =DERS_PLANI!AP213 -> 0
A8: 14.10 - 15.00 | B8: =DERS_PLANI!AP166 -> MYO - ETP 206 DIŞ TİCARET İŞLEMLERİ YÖNETİMİ | C8: =DERS_PLANI!AP178 -> MYO - TAP 206 YARATICI YAZARLIK | D8: =DERS_PLANI!AP190 -> MYO - TAP 228 Sanat Tarihi | E8: =DERS_PLANI!AP202 -> MYO - TAP 206 YARATICI YAZARLIK | F8: =DERS_PLANI!AP214 -> 0
A9: 15.20 - 16.10 | B9: =DERS_PLANI!AP167 -> 0 | C9: =DERS_PLANI!AP179 -> 0 | D9: =DERS_PLANI!AP191 -> 0 | E9: =DERS_PLANI!Q50 -> MYO - TAP222 Görsel Yapımlar İçin Ses Prodüksiyonu | F9: =DERS_PLANI!AP215 -> 0
A10: 16.15 - 17.05 | B10: =DERS_PLANI!AP168 -> 0 | C10: =DERS_PLANI!AP180 -> 0 | D10: =DERS_PLANI!AP192 -> 0 | E10: =DERS_PLANI!Q51 -> MYO - TAP222 Görsel Yapımlar İçin Ses Prodüksiyonu | F10: =DERS_PLANI!AP216 -> 0
A11: 17.10 - 18.00 | B11: =DERS_PLANI!AP169 -> 0 | C11: =DERS_PLANI!AP181 -> 0 | D11: =DERS_PLANI!AP193 -> 0 | E11: =DERS_PLANI!Q52 -> MYO - TAP222 Görsel Yapımlar İçin Ses Prodüksiyonu | F11: =DERS_PLANI!AP217 -> 0
A12: 18:10 -19:00 | B12: =DERS_PLANI!AP170 -> 0 | C12: =DERS_PLANI!AP182 -> 0 | D12: =DERS_PLANI!AP194 -> 0 | E12: =DERS_PLANI!AP206 -> 0 | F12: =DERS_PLANI!AP218 -> 0
A13: 19:10 - 20:00 | B13: =DERS_PLANI!AP171 -> 0 | C13: =DERS_PLANI!AP183 -> 0 | D13: =DERS_PLANI!AP195 -> 0 | E13: =DERS_PLANI!AP207 -> 0 | F13: =DERS_PLANI!AP219 -> 0
A14: 20:10 - 21:00 | B14: =DERS_PLANI!AP172 -> 0 | C14: =DERS_PLANI!AP184 -> 0 | D14: =DERS_PLANI!AP196 -> 0 | E14: =DERS_PLANI!AP208 -> 0 | F14: =DERS_PLANI!AP220 -> 0

Sheet C 085
A1: C 085
A2: Saat/Gün | B2: Pazartesi | C2: Salı | D2: Çarşamba | E2: Perşembe | F2: Cuma
A3: 09.00 - 09.50 | B3: =DERS_PLANI!AO161 -> 0 | C3: =DERS_PLANI!AO173 -> MYO - IHA202 ELEKTRONİK ALGILAYICILAR | D3: =DERS_PLANI!AO185 -> MYO - İHA204 MİKRODENETLEYİCİLER | E3: =DERS_PLANI!AO197 -> 0 | F3: =DERS_PLANI!AO209 -> 0
A4: 09.55 - 10.45 | B4: =DERS_PLANI!AO162 -> MYO - IHA112 TEMEL ELEKTRİK ve ELEKTRONİK ş1 | C4: =DERS_PLANI!AO174 -> MYO - IHA202 ELEKTRONİK ALGILAYICILAR | D4: =DERS_PLANI!AO186 -> MYO - İHA204 MİKRODENETLEYİCİLER | E4: =DERS_PLANI!AO198 -> 0 | F4: =DERS_PLANI!AO210 -> 0
A5: 10.50 - 11.40 | B5: =DERS_PLANI!AO163 -> MYO - IHA112 TEMEL ELEKTRİK ve ELEKTRONİK ş1 | C5: =DERS_PLANI!AO175 -> MYO - IHA202 ELEKTRONİK ALGILAYICILAR | D5: =DERS_PLANI!AO187 -> MYO - İHA204 MİKRODENETLEYİCİLER | E5: =DERS_PLANI!AO199 -> 0 | F5: =DERS_PLANI!AO211 -> 0
A6: 12.20 - 13.10 | B6: =DERS_PLANI!AO164 -> 0 | C6: =DERS_PLANI!AO176 -> 0 | D6: =DERS_PLANI!AO188 -> MYO - IHA 224 - SAYISAL ELEKTRONİK | E6: =DERS_PLANI!AO200 -> MYO - IHA 210 AERODİNAMİK VE AVİYONİK SİSTEM TASARIMI | F6: =DERS_PLANI!AO212 -> 0
A7: 13.15 - 14.05 | B7: =DERS_PLANI!AO165 -> 0 | C7: =DERS_PLANI!AO177 -> 0 | D7: =DERS_PLANI!AO189 -> MYO - IHA 224 - SAYISAL ELEKTRONİK | E7: =DERS_PLANI!AO201 -> MYO - IHA 210 AERODİNAMİK VE AVİYONİK SİSTEM TASARIMI | F7: =DERS_PLANI!AO213 -> 0
A8: 14.10 - 15.00 | B8: =DERS_PLANI!AO166 -> 0 | C8: =DERS_PLANI!AO178 -> 0 | D8: =DERS_PLANI!AO190 -> MYO - IHA 224 - SAYISAL ELEKTRONİK | E8: =DERS_PLANI!AO202 -> MYO - IHA 210 AERODİNAMİK VE AVİYONİK SİSTEM TASARIMI | F8: =DERS_PLANI!AO214 -> 0
A9: 15.20 - 16.10 | B9: =DERS_PLANI!AO167 -> 0 | C9: =DERS_PLANI!AO179 -> 0 | D9: =DERS_PLANI!AO191 -> 0 | E9: =DERS_PLANI!AO203 -> MYO - ETP 204 MARKA YÖNETİMİ | F9: =DERS_PLANI!AO215 -> 0
A10: 16.15 - 17.05 | B10: =DERS_PLANI!AO168 -> 0 | C10: =DERS_PLANI!AO180 -> 0 | D10: =DERS_PLANI!AO192 -> 0 | E10: =DERS_PLANI!AO204 -> MYO - ETP 204 MARKA YÖNETİMİ | F10: =DERS_PLANI!AO216 -> 0
A11: 17.10 - 18.00 | B11: =DERS_PLANI!AO169 -> 0 | C11: =DERS_PLANI!AO181 -> 0 | D11: =DERS_PLANI!AO193 -> 0 | E11: =DERS_PLANI!AO205 -> MYO - ETP 204 MARKA YÖNETİMİ | F11: =DERS_PLANI!AO217 -> 0
A12: 18:10 -19:00 | B12: =DERS_PLANI!AO170 -> 0 | C12: =DERS_PLANI!AO182 -> 0 | D12: =DERS_PLANI!AO194 -> 0 | E12: =DERS_PLANI!AO206 -> 0 | F12: =DERS_PLANI!AO218 -> 0
A13: 19:10 - 20:00 | B13: =DERS_PLANI!AO171 -> 0 | C13: =DERS_PLANI!AO183 -> 0 | D13: =DERS_PLANI!AO195 -> 0 | E13: =DERS_PLANI!AO207 -> 0 | F13: =DERS_PLANI!AO219 -> 0
A14: 20:10 - 21:00 | B14: =DERS_PLANI!AO172 -> 0 | C14: =DERS_PLANI!AO184 -> 0 | D14: =DERS_PLANI!AO196 -> 0 | E14: =DERS_PLANI!AO208 -> 0 | F14: =DERS_PLANI!AO220 -> 0

Sheet C 084
A1: C 084
A2: Saat/Gün | B2: Pazartesi | C2: Salı | D2: Çarşamba | E2: Perşembe | F2: Cuma
A3: 09.00 - 09.50 | B3: =DERS_PLANI!AN161 -> 0 | C3: =DERS_PLANI!AN173 -> 0 | D3: =DERS_PLANI!AN185 -> 0 | E3: =DERS_PLANI!AN197 -> 0 | F3: =DERS_PLANI!AN209 -> 0
A4: 09.55 - 10.45 | B4: =DERS_PLANI!AN162 -> 0 | C4: =DERS_PLANI!AN174 -> 0 | D4: =DERS_PLANI!AN186 -> 0 | E4: =DERS_PLANI!AN198 -> 0 | F4: =DERS_PLANI!AN210 -> 0
A5: 10.50 - 11.40 | B5: =DERS_PLANI!AN163 -> 0 | C5: =DERS_PLANI!AN175 -> 0 | D5: =DERS_PLANI!AN187 -> 0 | E5: =DERS_PLANI!AN199 -> 0 | F5: =DERS_PLANI!AN211 -> 0
A6: 12.20 - 13.10 | B6: =DERS_PLANI!AN164 -> 0 | C6: =DERS_PLANI!AN176 -> 0 | D6: =DERS_PLANI!AN188 -> 0 | E6: =DERS_PLANI!AN200 -> 0 | F6: =DERS_PLANI!AN212 -> 0
A7: 13.15 - 14.05 | B7: =DERS_PLANI!AN165 -> 0 | C7: =DERS_PLANI!AN177 -> 0 | D7: =DERS_PLANI!AN189 -> 0 | E7: =DERS_PLANI!AN201 -> 0 | F7: =DERS_PLANI!AN213 -> 0
A8: 14.10 - 15.00 | B8: =DERS_PLANI!AN166 -> 0 | C8: =DERS_PLANI!AN178 -> 0 | D8: =DERS_PLANI!AN190 -> 0 | E8: =DERS_PLANI!AN202 -> 0 | F8: =DERS_PLANI!AN214 -> 0
A9: 15.20 - 16.10 | B9: =DERS_PLANI!AN167 -> 0 | C9: =DERS_PLANI!AN179 -> 0 | D9: =DERS_PLANI!AN191 -> 0 | E9: =DERS_PLANI!AN203 -> 0 | F9: =DERS_PLANI!AN215 -> 0
A10: 16.15 - 17.05 | B10: =DERS_PLANI!AN168 -> 0 | C10: =DERS_PLANI!AN180 -> 0 | D10: =DERS_PLANI!AN192 -> 0 | E10: =DERS_PLANI!AN204 -> 0 | F10: =DERS_PLANI!AN216 -> 0
A11: 17.10 - 18.00 | B11: =DERS_PLANI!AN169 -> 0 | C11: =DERS_PLANI!AN181 -> 0 | D11: =DERS_PLANI!AN193 -> 0 | E11: =DERS_PLANI!AN205 -> 0 | F11: =DERS_PLANI!AN217 -> 0
A12: 18:10 -19:00 | B12: =DERS_PLANI!AN170 -> 0 | C12: =DERS_PLANI!AN182 -> 0 | D12: =DERS_PLANI!AN194 -> 0 | E12: =DERS_PLANI!AN206 -> 0 | F12: =DERS_PLANI!AN218 -> 0
A13: 19:10 - 20:00 | B13: =DERS_PLANI!AN171 -> 0 | C13: =DERS_PLANI!AN183 -> 0 | D13: =DERS_PLANI!AN195 -> 0 | E13: =DERS_PLANI!AN207 -> 0 | F13: =DERS_PLANI!AN219 -> 0
A14: 20:10 - 21:00 | B14: =DERS_PLANI!AN172 -> 0 | C14: =DERS_PLANI!AN184 -> 0 | D14: =DERS_PLANI!AN196 -> 0 | E14: =DERS_PLANI!AN208 -> 0 | F14: =DERS_PLANI!AN220 -> 0

Sheet C 078
A1: C 078
A2: Saat/Gün | B2: Pazartesi | C2: Salı | D2: Çarşamba | E2: Perşembe | F2: Cuma
A3: 09.00 - 09.50 | B3: =DERS_PLANI!AM161 -> 0 | C3: =DERS_PLANI!AM173 -> 0 | D3: =DERS_PLANI!AM185 -> 0 | E3: =DERS_PLANI!AM197 -> 0 | F3: =DERS_PLANI!AM209 -> 0
A4: 09.55 - 10.45 | B4: =DERS_PLANI!AM162 -> 0 | C4: =DERS_PLANI!AM174 -> 0 | D4: =DERS_PLANI!AM186 -> 0 | E4: =DERS_PLANI!AM198 -> 0 | F4: =DERS_PLANI!AM210 -> 0
A5: 10.50 - 11.40 | B5: =DERS_PLANI!AM163 -> 0 | C5: =DERS_PLANI!AM175 -> 0 | D5: =DERS_PLANI!AM187 -> 0 | E5: =DERS_PLANI!AM199 -> 0 | F5: =DERS_PLANI!AM211 -> 0
A6: 12.20 - 13.10 | B6: =DERS_PLANI!AM164 -> 0 | C6: =DERS_PLANI!AM176 -> 0 | D6: =DERS_PLANI!AM188 -> 0 | E6: =DERS_PLANI!AM200 -> 0 | F6: =DERS_PLANI!AM212 -> 0
A7: 13.15 - 14.05 | B7: =DERS_PLANI!AM165 -> 0 | C7: =DERS_PLANI!AM177 -> 0 | D7: =DERS_PLANI!AM189 -> 0 | E7: =DERS_PLANI!AM201 -> 0 | F7: =DERS_PLANI!AM213 -> 0
A8: 14.10 - 15.00 | B8: =DERS_PLANI!AM166 -> 0 | C8: =DERS_PLANI!AM178 -> 0 | D8: =DERS_PLANI!AM190 -> 0 | E8: =DERS_PLANI!AM202 -> 0 | F8: =DERS_PLANI!AM214 -> 0
A9: 15.20 - 16.10 | B9: =DERS_PLANI!AM167 -> 0 | C9: =DERS_PLANI!AM179 -> 0 | D9: =DERS_PLANI!AM191 -> 0 | E9: =DERS_PLANI!AM203 -> 0 | F9: =DERS_PLANI!AM215 -> 0
A10: 16.15 - 17.05 | B10: =DERS_PLANI!AM168 -> 0 | C10: =DERS_PLANI!AM180 -> 0 | D10: =DERS_PLANI!AM192 -> 0 | E10: =DERS_PLANI!AM204 -> 0 | F10: =DERS_PLANI!AM216 -> 0
A11: 17.10 - 18.00 | B11: =DERS_PLANI!AM169 -> 0 | C11: =DERS_PLANI!AM181 -> 0 | D11: =DERS_PLANI!AM193 -> 0 | E11: =DERS_PLANI!AM205 -> 0 | F11: =DERS_PLANI!AM217 -> 0
A12: 18:10 -19:00 | B12: =DERS_PLANI!AM170 -> 0 | C12: =DERS_PLANI!AM182 -> 0 | D12: =DERS_PLANI!AM194 -> 0 | E12: =DERS_PLANI!AM206 -> 0 | F12: =DERS_PLANI!AM218 -> 0
A13: 19:10 - 20:00 | B13: =DERS_PLANI!AM171 -> 0 | C13: =DERS_PLANI!AM183 -> 0 | D13: =DERS_PLANI!AM195 -> 0 | E13: =DERS_PLANI!AM207 -> 0 | F13: =DERS_PLANI!AM219 -> 0
A14: 20:10 - 21:00 | B14: =DERS_PLANI!AM172 -> 0 | C14: =DERS_PLANI!AM184 -> 0 | D14: =DERS_PLANI!AM196 -> 0 | E14: =DERS_PLANI!AM208 -> 0 | F14: =DERS_PLANI!AM220 -> 0

Sheet C 077
A1: C 077
A2: Saat/Gün | B2: Pazartesi | C2: Salı | D2: Çarşamba | E2: Perşembe | F2: Cuma
A3: 09.00 - 09.50 | B3: =DERS_PLANI!AL161 -> 0 | C3: =DERS_PLANI!AL173 -> 0 | D3: =DERS_PLANI!AL185 -> 0 | E3: =DERS_PLANI!AL197 -> 0 | F3: =DERS_PLANI!AL209 -> 0
A4: 09.55 - 10.45 | B4: =DERS_PLANI!AL162 -> 0 | C4: =DERS_PLANI!AL174 -> 0 | D4: =DERS_PLANI!AL186 -> 0 | E4: =DERS_PLANI!AL198 -> 0 | F4: =DERS_PLANI!AL210 -> 0
A5: 10.50 - 11.40 | B5: =DERS_PLANI!AL163 -> 0 | C5: =DERS_PLANI!AL175 -> 0 | D5: =DERS_PLANI!AL187 -> 0 | E5: =DERS_PLANI!AL199 -> 0 | F5: =DERS_PLANI!AL211 -> 0
A6: 12.20 - 13.10 | B6: =DERS_PLANI!AL164 -> 0 | C6: =DERS_PLANI!AL176 -> 0 | D6: =DERS_PLANI!AL188 -> 0 | E6: =DERS_PLANI!AL200 -> 0 | F6: =DERS_PLANI!AL212 -> 0
A7: 13.15 - 14.05 | B7: =DERS_PLANI!AL165 -> 0 | C7: =DERS_PLANI!AL177 -> 0 | D7: =DERS_PLANI!AL189 -> 0 | E7: =DERS_PLANI!AL201 -> 0 | F7: =DERS_PLANI!AL213 -> 0
A8: 14.10 - 15.00 | B8: =DERS_PLANI!AL166 -> 0 | C8: =DERS_PLANI!AL178 -> 0 | D8: =DERS_PLANI!AL190 -> 0 | E8: =DERS_PLANI!AL202 -> 0 | F8: =DERS_PLANI!AL214 -> 0
A9: 15.20 - 16.10 | B9: =DERS_PLANI!AL167 -> 0 | C9: =DERS_PLANI!AL179 -> 0 | D9: =DERS_PLANI!AL191 -> 0 | E9: =DERS_PLANI!AL203 -> 0 | F9: =DERS_PLANI!AL215 -> 0
A10: 16.15 - 17.05 | B10: =DERS_PLANI!AL168 -> 0 | C10: =DERS_PLANI!AL180 -> 0 | D10: =DERS_PLANI!AL192 -> 0 | E10: =DERS_PLANI!AL204 -> 0 | F10: =DERS_PLANI!AL216 -> 0
A11: 17.10 - 18.00 | B11: =DERS_PLANI!AL169 -> 0 | C11: =DERS_PLANI!AL181 -> 0 | D11: =DERS_PLANI!AL193 -> 0 | E11: =DERS_PLANI!AL205 -> 0 | F11: =DERS_PLANI!AL217 -> 0
A12: 18:10 -19:00 | B12: =DERS_PLANI!AL170 -> 0 | C12: =DERS_PLANI!AL182 -> 0 | D12: =DERS_PLANI!AL194 -> 0 | E12: =DERS_PLANI!AL206 -> 0 | F12: =DERS_PLANI!AL218 -> 0
A13: 19:10 - 20:00 | B13: =DERS_PLANI!AL171 -> 0 | C13: =DERS_PLANI!AL183 -> 0 | D13: =DERS_PLANI!AL195 -> 0 | E13: =DERS_PLANI!AL207 -> 0 | F13: =DERS_PLANI!AL219 -> 0
A14: 20:10 - 21:00 | B14: =DERS_PLANI!AL172 -> 0 | C14: =DERS_PLANI!AL184 -> 0 | D14: =DERS_PLANI!AL196 -> 0 | E14: =DERS_PLANI!AL208 -> 0 | F14: =DERS_PLANI!AL220 -> 0

Sheet C 076
A1: C 076
A2: Saat/Gün | B2: Pazartesi | C2: Salı | D2: Çarşamba | E2: Perşembe | F2: Cuma
A3: 09.00 - 09.50 | B3: =DERS_PLANI!AK161 -> 0 | C3: =DERS_PLANI!AK173 -> 0 | D3: =DERS_PLANI!AK185 -> 0 | E3: =DERS_PLANI!AK197 -> 0 | F3: =DERS_PLANI!AK209 -> 0
A4: 09.55 - 10.45 | B4: =DERS_PLANI!AK162 -> 0 | C4: =DERS_PLANI!AK174 -> 0 | D4: =DERS_PLANI!AK186 -> 0 | E4: =DERS_PLANI!AK198 -> 0 | F4: =DERS_PLANI!AK210 -> 0
A5: 10.50 - 11.40 | B5: =DERS_PLANI!AK163 -> 0 | C5: =DERS_PLANI!AK175 -> 0 | D5: =DERS_PLANI!AK187 -> 0 | E5: =DERS_PLANI!AK199 -> 0 | F5: =DERS_PLANI!AK211 -> 0
A6: 12.20 - 13.10 | B6: =DERS_PLANI!AK164 -> 0 | C6: =DERS_PLANI!AK176 -> 0 | D6: =DERS_PLANI!AK188 -> 0 | E6: =DERS_PLANI!AK200 -> 0 | F6: =DERS_PLANI!AK212 -> 0
A7: 13.15 - 14.05 | B7: =DERS_PLANI!AK165 -> 0 | C7: =DERS_PLANI!AK177 -> 0 | D7: =DERS_PLANI!AK189 -> 0 | E7: =DERS_PLANI!AK201 -> 0 | F7: =DERS_PLANI!AK213 -> 0
A8: 14.10 - 15.00 | B8: =DERS_PLANI!AK166 -> 0 | C8: =DERS_PLANI!AK178 -> 0 | D8: =DERS_PLANI!AK190 -> 0 | E8: =DERS_PLANI!AK202 -> 0 | F8: =DERS_PLANI!AK214 -> 0
A9: 15.20 - 16.10 | B9: =DERS_PLANI!AK167 -> 0 | C9: =DERS_PLANI!AK179 -> 0 | D9: =DERS_PLANI!AK191 -> 0 | E9: =DERS_PLANI!AK203 -> 0 | F9: =DERS_PLANI!AK215 -> 0
A10: 16.15 - 17.05 | B10: =DERS_PLANI!AK168 -> 0 | C10: =DERS_PLANI!AK180 -> 0 | D10: =DERS_PLANI!AK192 -> 0 | E10: =DERS_PLANI!AK204 -> 0 | F10: =DERS_PLANI!AK216 -> 0
A11: 17.10 - 18.00 | B11: =DERS_PLANI!AK169 -> 0 | C11: =DERS_PLANI!AK181 -> 0 | D11: =DERS_PLANI!AK193 -> 0 | E11: =DERS_PLANI!AK205 -> 0 | F11: =DERS_PLANI!AK217 -> 0
A12: 18:10 -19:00 | B12: =DERS_PLANI!AK170 -> 0 | C12: =DERS_PLANI!AK182 -> 0 | D12: =DERS_PLANI!AK194 -> 0 | E12: =DERS_PLANI!AK206 -> 0 | F12: =DERS_PLANI!AK218 -> 0
A13: 19:10 - 20:00 | B13: =DERS_PLANI!AK171 -> 0 | C13: =DERS_PLANI!AK183 -> 0 | D13: =DERS_PLANI!AK195 -> 0 | E13: =DERS_PLANI!AK207 -> 0 | F13: =DERS_PLANI!AK219 -> 0
A14: 20:10 - 21:00 | B14: =DERS_PLANI!AK172 -> 0 | C14: =DERS_PLANI!AK184 -> 0 | D14: =DERS_PLANI!AK196 -> 0 | E14: =DERS_PLANI!AK208 -> 0 | F14: =DERS_PLANI!AK220 -> 0

Sheet C 075
A1: C 075
A2: Saat/Gün | B2: Pazartesi | C2: Salı | D2: Çarşamba | E2: Perşembe | F2: Cuma
A3: 09.00 - 09.50 | B3: =DERS_PLANI!AJ161 -> 0 | C3: =DERS_PLANI!AJ173 -> MAT 224 Doğrusal Cebir ve Diferansiyel Denklemler (Mesut Altınok) | D3: =DERS_PLANI!AJ185 -> 0 | E3: =DERS_PLANI!AJ197 -> 0 | F3: =DERS_PLANI!AJ209 -> 0
A4: 09.55 - 10.45 | B4: =DERS_PLANI!AJ162 -> 0 | C4: =DERS_PLANI!AJ174 -> MAT 224 Doğrusal Cebir ve Diferansiyel Denklemler (Mesut Altınok) | D4: =DERS_PLANI!AJ186 -> 0 | E4: =DERS_PLANI!AJ198 -> 0 | F4: =DERS_PLANI!AJ210 -> 0
A5: 10.50 - 11.40 | B5: =DERS_PLANI!AJ163 -> 0 | C5: =DERS_PLANI!AJ175 -> MAT 224 Doğrusal Cebir ve Diferansiyel Denklemler (Mesut Altınok) | D5: =DERS_PLANI!AJ187 -> 0 | E5: =DERS_PLANI!AJ199 -> ING 202 - 01 | F5: =DERS_PLANI!AJ211 -> 0
A6: 12.20 - 13.10 | B6: =DERS_PLANI!AJ164 -> MAT 206 Olasılık Teorisi ve İstatistik (Mesut Altınok) | C6: =DERS_PLANI!AJ176 -> MYO - ETP 104 DİJİTAL PAZARLAMA | D6: =DERS_PLANI!AJ188 -> 0 | E6: =DERS_PLANI!AJ200 -> ING 202 - 01 | F6: =DERS_PLANI!AJ212 -> 0
A7: 13.15 - 14.05 | B7: =DERS_PLANI!AJ165 -> MAT 206 Olasılık Teorisi ve İstatistik (Mesut Altınok) | C7: =DERS_PLANI!AJ177 -> MYO - ETP 104 DİJİTAL PAZARLAMA | D7: =DERS_PLANI!AJ189 -> 0 | E7: =DERS_PLANI!AJ201 -> 0 | F7: =DERS_PLANI!AJ213 -> 0
A8: 14.10 - 15.00 | B8: =DERS_PLANI!AJ166 -> MAT 206 Olasılık Teorisi ve İstatistik (Mesut Altınok) | C8: =DERS_PLANI!AJ178 -> MYO - ETP 104 DİJİTAL PAZARLAMA | D8: =DERS_PLANI!AJ190 -> 0 | E8: =DERS_PLANI!AJ202 -> 0 | F8: =DERS_PLANI!AJ214 -> 0
A9: 15.20 - 16.10 | B9: =DERS_PLANI!AJ167 -> 0 | C9: =DERS_PLANI!#REF! -> #REF! | D9: =DERS_PLANI!AJ191 -> 0 | E9: =DERS_PLANI!AJ203 -> 0 | F9: =DERS_PLANI!AJ215 -> 0
A10: 16.15 - 17.05 | B10: =DERS_PLANI!AJ168 -> 0 | C10: =DERS_PLANI!#REF! -> #REF! | D10: =DERS_PLANI!AJ192 -> 0 | E10: =DERS_PLANI!AJ204 -> 0 | F10: =DERS_PLANI!AJ216 -> 0
A11: 17.10 - 18.00 | B11: =DERS_PLANI!AJ169 -> 0 | C11: =DERS_PLANI!#REF! -> #REF! | D11: =DERS_PLANI!AJ193 -> 0 | E11: =DERS_PLANI!AJ205 -> 0 | F11: =DERS_PLANI!AJ217 -> 0
A12: 18:10 -19:00 | B12: =DERS_PLANI!AJ170 -> 0 | C12: =DERS_PLANI!AJ182 -> 0 | D12: =DERS_PLANI!AJ194 -> 0 | E12: =DERS_PLANI!AJ206 -> 0 | F12: =DERS_PLANI!AJ218 -> 0
A13: 19:10 - 20:00 | B13: =DERS_PLANI!AJ171 -> 0 | C13: =DERS_PLANI!AJ183 -> 0 | D13: =DERS_PLANI!AJ195 -> 0 | E13: =DERS_PLANI!AJ207 -> 0 | F13: =DERS_PLANI!AJ219 -> 0
A14: 20:10 - 21:00 | B14: =DERS_PLANI!AJ172 -> 0 | C14: =DERS_PLANI!AJ184 -> 0 | D14: =DERS_PLANI!AJ196 -> 0 | E14: =DERS_PLANI!AJ208 -> 0 | F14: =DERS_PLANI!AJ220 -> 0

Sheet C 074
A1: C 074
A2: Saat/Gün | B2: Pazartesi | C2: Salı | D2: Çarşamba | E2: Perşembe | F2: Cuma
A3: 09.00 - 09.50 | B3: =DERS_PLANI!AI161 -> 0 | C3: =DERS_PLANI!AI173 -> 0 | D3: =DERS_PLANI!AI185 -> 0 | E3: =DERS_PLANI!AI197 -> 0 | F3: =DERS_PLANI!AI209 -> MYO - BGT204 Bilişim Hukuku
A4: 09.55 - 10.45 | B4: =DERS_PLANI!AI162 -> ENG 202 - 10 | C4: =DERS_PLANI!AI174 -> ENG 102 - 8 | D4: =DERS_PLANI!AI186 -> MAT 102 (Teorik) - Sec 1(Mesut Altunok) | E4: =DERS_PLANI!AI198 -> 0 | F4: =DERS_PLANI!AI210 -> MYO - BGT204 Bilişim Hukuku
A5: 10.50 - 11.40 | B5: =DERS_PLANI!AI163 -> ENG 202 - 10 | C5: =DERS_PLANI!AI175 -> ENG 102 - 8 | D5: =DERS_PLANI!AI187 -> MAT 102 (Teorik) - Sec 1(Mesut Altunok) | E5: =DERS_PLANI!AI199 -> 0 | F5: =DERS_PLANI!AI211 -> MYO - BGT204 Bilişim Hukuku
A6: 12.20 - 13.10 | B6: =DERS_PLANI!AI164 -> EEE 236 (Teorik) - Sec 1 (Parisa Akar) | C6: =DERS_PLANI!AI176 -> ENG 202 - 11 | D6: =DERS_PLANI!AI188 -> 0 | E6: =DERS_PLANI!AI200 -> 0 | F6: =DERS_PLANI!AI212 -> 0
A7: 13.15 - 14.05 | B7: =DERS_PLANI!AI165 -> EEE 236 (Teorik) - Sec 1 (Parisa Akar) | C7: =DERS_PLANI!AI177 -> ENG 202 - 11 | D7: =DERS_PLANI!AI189 -> 0 | E7: =DERS_PLANI!AI201 -> ENG 102 - 9 | F7: =DERS_PLANI!AI213 -> 0
A8: 14.10 - 15.00 | B8: =DERS_PLANI!AI166 -> EEE 236 (Teorik) - Sec 1 (Parisa Akar) | C8: =DERS_PLANI!AI178 -> 0 | D8: =DERS_PLANI!AI190 -> 0 | E8: =DERS_PLANI!AI202 -> ENG 102 - 9 | F8: =DERS_PLANI!AI214 -> 0
A9: 15.20 - 16.10 | B9: =DERS_PLANI!AI167 -> MATH 206 (Teorik) - Sec 1 (Benhür Satır) | C9: =DERS_PLANI!AI179 -> BM 324 (Teorik) - Sec 1 (Yüksel Arslan) | D9: =DERS_PLANI!AI191 -> ENG 202 - 13 | E9: =DERS_PLANI!AI203 -> ENG 302 - 11 | F9: =DERS_PLANI!AI215 -> 0
A10: 16.15 - 17.05 | B10: =DERS_PLANI!AI168 -> MATH 206 (Teorik) - Sec 1 (Benhür Satır) | C10: =DERS_PLANI!AI180 -> BM 324 (Teorik) - Sec 1 (Yüksel Arslan) | D10: =DERS_PLANI!AI192 -> ENG 202 - 13 | E10: =DERS_PLANI!AI204 -> ENG 302 - 11 | F10: =DERS_PLANI!AI216 -> 0
A11: 17.10 - 18.00 | B11: =DERS_PLANI!AI169 -> MATH 206 (Teorik) - Sec 1 (Benhür Satır) | C11: =DERS_PLANI!AI181 -> BM 324 (Teorik) - Sec 1 (Yüksel Arslan) | D11: =DERS_PLANI!AI193 -> 0 | E11: =DERS_PLANI!AI205 -> 0 | F11: =DERS_PLANI!AI217 -> 0
A12: 18:10 -19:00 | B12: =DERS_PLANI!AI170 -> 0 | C12: =DERS_PLANI!AI182 -> 0 | D12: =DERS_PLANI!AI194 -> 0 | E12: =DERS_PLANI!AI206 -> 0 | F12: =DERS_PLANI!AI218 -> 0
A13: 19:10 - 20:00 | B13: =DERS_PLANI!AI171 -> 0 | C13: =DERS_PLANI!AI183 -> 0 | D13: =DERS_PLANI!AI195 -> 0 | E13: =DERS_PLANI!AI207 -> 0 | F13: =DERS_PLANI!AI219 -> 0
A14: 20:10 - 21:00 | B14: =DERS_PLANI!AI172 -> 0 | C14: =DERS_PLANI!AI184 -> 0 | D14: =DERS_PLANI!AI196 -> 0 | E14: =DERS_PLANI!AI208 -> 0 | F14: =DERS_PLANI!AI220 -> 0

Sheet C 073
A1: C-073
A2: Saat/Gün | B2: Pazartesi | C2: Salı | D2: Çarşamba | E2: Perşembe | F2: Cuma
A3: 09:10-10:00 | B3: =DERS_PLANI!AH161 -> PSİ 221 | C3: =DERS_PLANI!AH173 -> HUK414 | D3: =DERS_PLANI!AH185 -> HUK408 | E3: =DERS_PLANI!AH197 -> 0 | F3: =DERS_PLANI!AH209 -> PSİ 104
A4: 10:10-11:00 | B4: =DERS_PLANI!AH162 -> PSİ 221 | C4: =DERS_PLANI!AH174 -> HUK414 | D4: =DERS_PLANI!AH186 -> HUK408 | E4: =DERS_PLANI!AH198 -> ENG 102 -01 (PSY) | F4: =DERS_PLANI!AH210 -> PSİ 104
A5: 11:10-12:00 | B5: =DERS_PLANI!AH163 -> PSİ 221 | C5: =DERS_PLANI!AH175 -> HUK414 | D5: =DERS_PLANI!AH187 -> HUK408 | E5: =DERS_PLANI!AH199 -> ENG 102 -01 (PSY) | F5: =DERS_PLANI!AH211 -> PSİ 104
A6: 12:10-13:00 | B6: =DERS_PLANI!AH164 -> MIS 222 / BUS 204 (Dr. Bayar) | C6: =DERS_PLANI!AH176 -> PSİ 322 | D6: =DERS_PLANI!AH188 -> PSİ 229 | E6: =DERS_PLANI!AH200 -> PSİ 342 | F6: =DERS_PLANI!AH212 -> 0
A7: 13:10-14:00 | B7: =DERS_PLANI!AH165 -> MIS 222 / BUS 204 (Dr. Bayar) | C7: =DERS_PLANI!AH177 -> PSİ 322 | D7: =DERS_PLANI!AH189 -> PSİ 229 | E7: =DERS_PLANI!AH201 -> PSİ 342 | F7: =DERS_PLANI!AH213 -> 0
A8: 14:10-15:00 | B8: =DERS_PLANI!AH166 -> MIS 222 / BUS 204 (Dr. Bayar) | C8: =DERS_PLANI!AH178 -> PSİ 322 | D8: =DERS_PLANI!AH190 -> PSİ 229 | E8: =DERS_PLANI!AH202 -> PSİ 342 | F8: =DERS_PLANI!AH214 -> 0
A9: 15:10-16:00 | B9: =DERS_PLANI!AH167 -> PSİ 313 | C9: =DERS_PLANI!AH179 -> PSİ 451 | D9: =DERS_PLANI!AH191 -> PSY 219 | E9: =DERS_PLANI!AH203 -> 0 | F9: =DERS_PLANI!AH215 -> 0
A10: 16:10-17:00 | B10: =DERS_PLANI!AH168 -> PSİ 313 | C10: =DERS_PLANI!AH180 -> PSİ 451 | D10: =DERS_PLANI!AH192 -> PSY 219 | E10: =DERS_PLANI!AH204 -> 0 | F10: =DERS_PLANI!AH216 -> 0
A11: 17:10-18:00 | B11: =DERS_PLANI!AH169 -> PSİ 313 | C11: =DERS_PLANI!AH181 -> PSİ 451 | D11: =DERS_PLANI!AH193 -> PSY 219 | E11: =DERS_PLANI!AH205 -> 0 | F11: =DERS_PLANI!AH217 -> 0
A12: 18:10 -19:00 | B12: =DERS_PLANI!AH170 -> 0 | C12: =DERS_PLANI!AH182 -> 0 | D12: =DERS_PLANI!AH194 -> 0 | E12: =DERS_PLANI!AH206 -> 0 | F12: =DERS_PLANI!AH218 -> 0
A13: 19:10 - 20:00 | B13: =DERS_PLANI!AH171 -> 0 | C13: =DERS_PLANI!AH183 -> 0 | D13: =DERS_PLANI!AH195 -> 0 | E13: =DERS_PLANI!AH207 -> 0 | F13: =DERS_PLANI!AH219 -> 0
A14: 20:10 - 21:00 | B14: =DERS_PLANI!AH172 -> 0 | C14: =DERS_PLANI!AH184 -> 0 | D14: =DERS_PLANI!AH196 -> 0 | E14: =DERS_PLANI!AH208 -> 0 | F14: =DERS_PLANI!AH220 -> 0

Sheet C 072
A1: C 072
A2: Saat/Gün | B2: Pazartesi | C2: Salı | D2: Çarşamba | E2: Perşembe | F2: Cuma
A3: 09.00 - 09.50 | B3: =DERS_PLANI!AG161 -> MYOETP 102 E-TİCARET ve ENTEGRASYON | C3: =DERS_PLANI!AG173 -> 0 | D3: =DERS_PLANI!AG185 -> 0 | E3: =DERS_PLANI!AG197 -> 0 | F3: =DERS_PLANI!AG209 -> 0
A4: 09.55 - 10.45 | B4: =DERS_PLANI!AG162 -> MYOETP 102 E-TİCARET ve ENTEGRASYON | C4: =DERS_PLANI!AG174 -> 0 | D4: =DERS_PLANI!AG186 -> 0 | E4: =DERS_PLANI!AG198 -> ING 302 - 01 (MMF BILG. MUH. TR) | F4: =DERS_PLANI!AG210 -> 0
A5: 10.50 - 11.40 | B5: =DERS_PLANI!AG163 -> MYOETP 102 E-TİCARET ve ENTEGRASYON | C5: =DERS_PLANI!AG175 -> 0 | D5: =DERS_PLANI!AG187 -> SİMURG SEÇMELİ | E5: =DERS_PLANI!AG199 -> ING 302 - 01 (MMF BILG. MUH. TR) | F5: =DERS_PLANI!AG211 -> 0
A6: 12.20 - 13.10 | B6: =DERS_PLANI!AG164 -> MYO - ETP 106 ONLINE SATIŞ PLATFORMLARI | C6: =DERS_PLANI!AG176 -> MYO - IHA208 SİSTEM DİNAMİĞİ | D6: =DERS_PLANI!AG188 -> SİMURG MASTERCLASS | E6: =DERS_PLANI!AG200 -> 0 | F6: =DERS_PLANI!AG212 -> 0
A7: 13.15 - 14.05 | B7: =DERS_PLANI!AG165 -> MYO - ETP 106 ONLINE SATIŞ PLATFORMLARI | C7: =DERS_PLANI!AG177 -> MYO - IHA208 SİSTEM DİNAMİĞİ | D7: =DERS_PLANI!AG189 -> SİMURG MASTERCLASS | E7: =DERS_PLANI!AG201 -> 0 | F7: =DERS_PLANI!AG213 -> 0
A8: 14.10 - 15.00 | B8: =DERS_PLANI!AG166 -> MYO - ETP 106 ONLINE SATIŞ PLATFORMLARI | C8: =DERS_PLANI!AG178 -> MYO - IHA208 SİSTEM DİNAMİĞİ | D8: =DERS_PLANI!AG190 -> SİMURG MASTERCLASS | E8: =DERS_PLANI!AG202 -> 0 | F8: =DERS_PLANI!AG214 -> 0
A9: 15.20 - 16.10 | B9: =DERS_PLANI!AG167 -> 0 | C9: =DERS_PLANI!AG179 -> 0 | D9: =DERS_PLANI!AG191 -> SİMURG MASTERCLASS | E9: =DERS_PLANI!AG203 -> MYO - IHA112 TEMEL ELEKTRİK ve ELEKTRONİK | F9: =DERS_PLANI!AG215 -> 0
